Workbook

Sheet RNA
A1: number | B1: tube_ID | C1: freezer_location | D1: BOX_number | E1: species | F1: mussel_ID | G1: tissue | H1: treatment | I1: sort_ID | J1: both_thread | K1: priority
A2: 121 | B2: G01-F | C2: 9-1-1 | D2: 1 | E2: =if(left(F2,1)="G","gallo","tross") -> gallo | F2: G01 | G2: foot | H2: gallo-control-0 | I2: gallo-control-0-foot | J2: =vlookup(F2,'mussel-ID_key'!A:C,3,false) -> 0
A3: 133 | B3: G01-G | C3: 9-1-1 | D3: 1 | E3: =if(left(F3,1)="G","gallo","tross") -> gallo | F3: G01 | G3: gill | H3: gallo-control-0 | I3: gallo-control-0-gill | J3: =vlookup(F3,'mussel-ID_key'!A:C,3,false) -> 0
A4: 122 | B4: G02-F | C4: 9-1-1 | D4: 1 | E4: =if(left(F4,1)="G","gallo","tross") -> gallo | F4: G02 | G4: foot | H4: gallo-control-0 | I4: gallo-control-0-foot | J4: =vlookup(F4,'mussel-ID_key'!A:C,3,false) -> 0
A5: 134 | B5: G02-G | C5: 9-1-1 | D5: 1 | E5: =if(left(F5,1)="G","gallo","tross") -> gallo | F5: G02 | G5: gill | H5: gallo-control-0 | I5: gallo-control-0-gill | J5: =vlookup(F5,'mussel-ID_key'!A:C,3,false) -> 0
A6: 123 | B6: G03-F | C6: 9-1-1 | D6: 1 | E6: gallo | F6: G03 | G6: foot | H6: gallo-control-0 | I6: gallo-control-0-foot | J6: =vlookup(F6,'mussel-ID_key'!A:C,3,false) -> 0
A7: 135 | B7: G03-G | C7: 9-1-1 | D7: 1 | E7: =if(left(F7,1)="G","gallo","tross") -> gallo | F7: G03 | G7: gill | H7: gallo-control-0 | I7: gallo-control-0-gill | J7: =vlookup(F7,'mussel-ID_key'!A:C,3,false) -> 0
A8: 124 | B8: G04-F | C8: 9-1-1 | D8: 1 | E8: =if(left(F8,1)="G","gallo","tross") -> gallo | F8: G04 | G8: foot | H8: gallo-control-0 | I8: gallo-control-0-foot | J8: =vlookup(F8,'mussel-ID_key'!A:C,3,false) -> 0
A9: 136 | B9: G04-G | C9: 9-1-1 | D9: 1 | E9: =if(left(F9,1)="G","gallo","tross") -> gallo | F9: G04 | G9: gill | H9: gallo-control-0 | I9: gallo-control-0-gill | J9: =vlookup(F9,'mussel-ID_key'!A:C,3,false) -> 0
A10: 125 | B10: G05-F | C10: 9-1-1 | D10: 1 | E10: =if(left(F10,1)="G","gallo","tross") -> gallo | F10: G05 | G10: foot | H10: gallo-control-0 | I10: gallo-control-0-foot | J10: =vlookup(F10,'mussel-ID_key'!A:C,3,false) -> 0
A11: 137 | B11: G05-G | C11: 9-1-1 | D11: 1 | E11: =if(left(F11,1)="G","gallo","tross") -> gallo | F11: G05 | G11: gill | H11: gallo-control-0 | I11: gallo-control-0-gill | J11: =vlookup(F11,'mussel-ID_key'!A:C,3,false) -> 0
A12: 126 | B12: G06-F | C12: 9-1-1 | D12: 1 | E12: =if(left(F12,1)="G","gallo","tross") -> gallo | F12: G06 | G12: foot | H12: gallo-control-0 | I12: gallo-control-0-foot | J12: =vlookup(F12,'mussel-ID_key'!A:C,3,false) -> 0
A13: 138 | B13: G06-G | C13: 9-1-1 | D13: 1 | E13: =if(left(F13,1)="G","gallo","tross") -> gallo | F13: G06 | G13: gill | H13: gallo-control-0 | I13: gallo-control-0-gill | J13: =vlookup(F13,'mussel-ID_key'!A:C,3,false) -> 0
A14: 127 | B14: G07-F | C14: 9-1-1 | D14: 1 | E14: =if(left(F14,1)="G","gallo","tross") -> gallo | F14: G07 | G14: foot | H14: gallo-control-0 | I14: gallo-control-0-foot | J14: =vlookup(F14,'mussel-ID_key'!A:C,3,false) -> 0
A15: 139 | B15: G07-G | C15: 9-1-1 | D15: 1 | E15: =if(left(F15,1)="G","gallo","tross") -> gallo | F15: G07 | G15: gill | H15: gallo-control-0 | I15: gallo-control-0-gill | J15: =vlookup(F15,'mussel-ID_key'!A:C,3,false) -> 0
A16: 128 | B16: G08-F | C16: 9-1-1 | D16: 1 | E16: =if(left(F16,1)="G","gallo","tross") -> gallo | F16: G08 | G16: foot | H16: gallo-control-0 | I16: gallo-control-0-foot | J16: =vlookup(F16,'mussel-ID_key'!A:C,3,false) -> 0
A17: 140 | B17: G08-G | C17: 9-1-1 | D17: 1 | E17: =if(left(F17,1)="G","gallo","tross") -> gallo | F17: G08 | G17: gill | H17: gallo-control-0 | I17: gallo-control-0-gill | J17: =vlookup(F17,'mussel-ID_key'!A:C,3,false) -> 0
A18: 129 | B18: G09-F | C18: 9-1-1 | D18: 1 | E18: =if(left(F18,1)="G","gallo","tross") -> gallo | F18: G09 | G18: foot | H18: gallo-control-0 | I18: gallo-control-0-foot | J18: =vlookup(F18,'mussel-ID_key'!A:C,3,false) -> 0
... A109: 168 | B109: G90-G | C109: 9-1-5 | D109: 5 | E109: =if(left(F109,1)="G","gallo","tross") -> gallo | F109: G90 | G109: gill | H109: gallo-control-3 | I109: gallo-control-3-gill | J109: =vlookup(F109,'mussel-ID_key'!A:C,3,false) -> 0
A110: 1 | B110: T01-F | C110: 9-1-1 | D110: 1 | E110: =if(left(F110,1)="G","gallo","tross") -> tross | F110: T01 | G110: foot | H110: tross-control-0 | I110: tross-control-0-foot | J110: =vlookup(F110,'mussel-ID_key'!A:C,3,false) -> 0 | K110: High
A111: 13 | B111: T01-G | C111: 9-1-1 | D111: 1 | E111: =if(left(F111,1)="G","gallo","tross") -> tross | F111: T01 | G111: gill | H111: tross-control-0 | I111: tross-control-0-gill | J111: =vlookup(F111,'mussel-ID_key'!A:C,3,false) -> 0 | K111: High
A112: 2 | B112: T02-F | C112: 9-1-1 | D112: 1 | E112: =if(left(F112,1)="G","gallo","tross") -> tross | F112: T02 | G112: foot | H112: tross-control-0 | I112: tross-control-0-foot | J112: =vlookup(F112,'mussel-ID_key'!A:C,3,false) -> 0 | K112: High
A113: 14 | B113: T02-G | C113: 9-1-1 | D113: 1 | E113: =if(left(F113,1)="G","gallo","tross") -> tross | F113: T02 | G113: gill | H113: tross-control-0 | I113: tross-control-0-gill | J113: =vlookup(F113,'mussel-ID_key'!A:C,3,false) -> 0 | K113: High
A114: 3 | B114: T03-F | C114: 9-1-1 | D114: 1 | E114: =if(left(F114,1)="G","gallo","tross") -> tross | F114: T03 | G114: foot | H114: tross-control-0 | I114: tross-control-0-foot | J114: =vlookup(F114,'mussel-ID_key'!A:C,3,false) -> 0 | K114: High
A115: 15 | B115: T03-G | C115: 9-1-1 | D115: 1 | E115: =if(left(F115,1)="G","gallo","tross") -> tross | F115: T03 | G115: gill | H115: tross-control-0 | I115: tross-control-0-gill | J115: =vlookup(F115,'mussel-ID_key'!A:C,3,false) -> 0 | K115: High
A116: 4 | B116: T04-F | C116: 9-1-1 | D116: 1 | E116: =if(left(F116,1)="G","gallo","tross") -> tross | F116: T04 | G116: foot | H116: tross-control-0 | I116: tross-control-0-foot | J116: =vlookup(F116,'mussel-ID_key'!A:C,3,false) -> 0 | K116: High
A117: 16 | B117: T04-G | C117: 9-1-1 | D117: 1 | E117: =if(left(F117,1)="G","gallo","tross") -> tross | F117: T04 | G117: gill | H117: tross-control-0 | I117: tross-control-0-gill | J117: =vlookup(F117,'mussel-ID_key'!A:C,3,false) -> 0 | K117: High
A118: 5 | B118: T05-F | C118: 9-1-1 | D118: 1 | E118: =if(left(F118,1)="G","gallo","tross") -> tross | F118: T05 | G118: foot | H118: tross-control-0 | I118: tross-control-0-foot | J118: =vlookup(F118,'mussel-ID_key'!A:C,3,false) -> 0 | K118: High
A119: 17 | B119: T05-G | C119: 9-1-1 | D119: 1 | E119: =if(left(F119,1)="G","gallo","tross") -> tross | F119: T05 | G119: gill | H119: tross-control-0 | I119: tross-control-0-gill | J119: =vlookup(F119,'mussel-ID_key'!A:C,3,false) -> 0 | K119: High
A120: 6 | B120: T06-F | C120: 9-1-1 | D120: 1 | E120: =if(left(F120,1)="G","gallo","tross") -> tross | F120: T06 | G120: foot | H120: tross-control-0 | I120: tross-control-0-foot | J120: =vlookup(F120,'mussel-ID_key'!A:C,3,false) -> 0 | K120: High
A121: 18 | B121: T06-G | C121: 9-1-1 | D121: 1 | E121: =if(left(F121,1)="G","gallo","tross") -> tross | F121: T06 | G121: gill | H121: tross-control-0 | I121: tross-control-0-gill | J121: =vlookup(F121,'mussel-ID_key'!A:C,3,false) -> 0 | K121: High
... A132: 49 | B132: T110-F | C132: 9-1-4 | D132: 4 | E132: =if(left(F132,1)="G","gallo","tross") -> tross | F132: T110 | G132: foot | H132: tross-DO-3 | I132: tross-DO-3-foot | J132: =vlookup(F132,'mussel-ID_key'!A:C,3,false) -> 0 | K132: High
A133: 61 | B133: T110-G | C133: 9-1-5 | D133: 5 | E133: tross | F133: T110 | G133: gill | H133: tross-DO-3 | I133: tross-DO-3-gill | J133: =vlookup(F133,'mussel-ID_key'!A:C,3,false) -> 0 | K133: High
A134: 50 | B134: T111-F | C134: 9-1-4 | D134: 4 | E134: =if(left(F134,1)="G","gallo","tross") -> tross | F134: T111 | G134: foot | H134: tross-DO-3 | I134: tross-DO-3-foot | J134: =vlookup(F134,'mussel-ID_key'!A:C,3,false) -> 0 | K134: High
A135: 62 | B135: T111-G | C135: 9-1-5 | D135: 5 | E135: tross | F135: T111 | G135: gill | H135: tross-DO-3 | I135: tross-DO-3-gill | J135: =vlookup(F135,'mussel-ID_key'!A:C,3,false) -> 0 | K135: High
A136: 51 | B136: T112-F | C136: 9-1-4 | D136: 4 | E136: =if(left(F136,1)="G","gallo","tross") -> tross | F136: T112 | G136: foot | H136: tross-DO-3 | I136: tross-DO-3-foot | J136: =vlookup(F136,'mussel-ID_key'!A:C,3,false) -> 0 | K136: High
A137: 63 | B137: T112-G | C137: 9-1-5 | D137: 5 | E137: tross | F137: T112 | G137: gill | H137: tross-DO-3 | I137: tross-DO-3-gill | J137: =vlookup(F137,'mussel-ID_key'!A:C,3,false) -> 0 | K137: High
A138: 73 | B138: T118-F | C138: 9-1-4 | D138: 4 | E138: =if(left(F138,1)="G","gallo","tross") -> tross | F138: T118 | G138: foot | H138: tross-OA-3 | I138: tross-OA-3-foot | J138: =vlookup(F138,'mussel-ID_key'!A:C,3,false) -> 0 | K138: High
A139: 85 | B139: T118-G | C139: 9-1-3 | D139: 3 | E139: =if(left(F139,1)="G","gallo","tross") -> tross | F139: T118 | G139: gill | H139: tross-OA-3 | I139: tross-OA-3-gill | J139: =vlookup(F139,'mussel-ID_key'!A:C,3,false) -> 0 | K139: High
A140: 74 | B140: T119-F | C140: 9-1-4 | D140: 4 | E140: =if(left(F140,1)="G","gallo","tross") -> tross | F140: T119 | G140: foot | H140: tross-OA-3 | I140: tross-OA-3-foot | J140: =vlookup(F140,'mussel-ID_key'!A:C,3,false) -> 0 | K140: High
...

Sheet all-samples
A1: freezer_location | B1: BOX_number | C1: species | D1: mussel_ID | E1: tube_ID | F1: tissue | G1: treatment | H1: combo | I1: both_thread | J1: freezer_location | L1: treatment_summary | M1: count
A2: 9-1-1 | B2: 1 | C2: =if(left(D2,1)="G","gallo","tross") -> gallo | D2: G01 | E2: G01-F | F2: foot | G2: =vlookup(D2,'mussel-ID_key'!A:B,2,false) -> gallo-control-0 | H2: =G2&"-"&F2 -> gallo-control-0-foot | I2: =vlookup(D2,'mussel-ID_key'!A:C,3,false) -> 0 | J2: 9-1-1 | L2: gallo-control-0-foot | M2: =countif(H:H,L2) -> 10
A3: 9-1-1 | B3: 1 | C3: =if(left(D3,1)="G","gallo","tross") -> gallo | D3: G02 | E3: G02-F | F3: foot | G3: =vlookup(D3,'mussel-ID_key'!A:B,2,false) -> gallo-control-0 | H3: =G3&"-"&F3 -> gallo-control-0-foot | I3: =vlookup(D3,'mussel-ID_key'!A:C,3,false) -> 0 | J3: 9-1-1 | L3: gallo-control-3-foot | M3: =countif(H:H,L3) -> 12
A4: 9-1-1 | B4: 1 | C4: =if(left(D4,1)="G","gallo","tross") -> gallo | D4: G04 | E4: G04-F | F4: foot | G4: =vlookup(D4,'mussel-ID_key'!A:B,2,false) -> gallo-control-0 | H4: =G4&"-"&F4 -> gallo-control-0-foot | I4: =vlookup(D4,'mussel-ID_key'!A:C,3,false) -> 0 | J4: 9-1-1 | L4: gallo-DO-3-foot | M4: =countif(H:H,L4) -> 13
A5: 9-1-1 | B5: 1 | C5: =if(left(D5,1)="G","gallo","tross") -> gallo | D5: G05 | E5: G05-F | F5: foot | G5: =vlookup(D5,'mussel-ID_key'!A:B,2,false) -> gallo-control-0 | H5: =G5&"-"&F5 -> gallo-control-0-foot | I5: =vlookup(D5,'mussel-ID_key'!A:C,3,false) -> 0 | J5: 9-1-1 | L5: gallo-OA-3-foot | M5: =countif(H:H,L5) -> 9
A6: 9-1-1 | B6: 1 | C6: =if(left(D6,1)="G","gallo","tross") -> gallo | D6: G06 | E6: G06-F | F6: foot | G6: =vlookup(D6,'mussel-ID_key'!A:B,2,false) -> gallo-control-0 | H6: =G6&"-"&F6 -> gallo-control-0-foot | I6: =vlookup(D6,'mussel-ID_key'!A:C,3,false) -> 0 | J6: 9-1-1 | L6: gallo-OW-3-foot | M6: =countif(H:H,L6) -> 9
A7: 9-1-1 | B7: 1 | C7: =if(left(D7,1)="G","gallo","tross") -> gallo | D7: G07 | E7: G07-F | F7: foot | G7: =vlookup(D7,'mussel-ID_key'!A:B,2,false) -> gallo-control-0 | H7: =G7&"-"&F7 -> gallo-control-0-foot | I7: =vlookup(D7,'mussel-ID_key'!A:C,3,false) -> 0 | J7: 9-1-1
A8: 9-1-1 | B8: 1 | C8: =if(left(D8,1)="G","gallo","tross") -> gallo | D8: G09 | E8: G09-F | F8: foot | G8: =vlookup(D8,'mussel-ID_key'!A:B,2,false) -> gallo-control-0 | H8: =G8&"-"&F8 -> gallo-control-0-foot | I8: =vlookup(D8,'mussel-ID_key'!A:C,3,false) -> 0 | J8: 9-1-1 | L8: tross-control-0-foot | M8: =countif(H:H,L8) -> 16
A9: 9-1-1 | B9: 1 | C9: =if(left(D9,1)="G","gallo","tross") -> gallo | D9: G10 | E9: G10-F | F9: foot | G9: =vlookup(D9,'mussel-ID_key'!A:B,2,false) -> gallo-control-0 | H9: =G9&"-"&F9 -> gallo-control-0-foot | I9: =vlookup(D9,'mussel-ID_key'!A:C,3,false) -> 0 | J9: 9-1-1 | L9: tross-control-3-mantle | M9: =countif(H:H,L9) -> 12
A10: 9-1-1 | B10: 1 | C10: =if(left(D10,1)="G","gallo","tross") -> gallo | D10: G11 | E10: G11-F | F10: foot | G10: =vlookup(D10,'mussel-ID_key'!A:B,2,false) -> gallo-control-0 | H10: =G10&"-"&F10 -> gallo-control-0-foot | I10: =vlookup(D10,'mussel-ID_key'!A:C,3,false) -> 0 | J10: 9-1-1 | L10: tross-DO-3-foot | M10: =countif(H:H,L10) -> 18
A11: 9-1-1 | B11: 1 | C11: =if(left(D11,1)="G","gallo","tross") -> gallo | D11: G12 | E11: G12-F | F11: foot | G11: =vlookup(D11,'mussel-ID_key'!A:B,2,false) -> gallo-control-0 | H11: =G11&"-"&F11 -> gallo-control-0-foot | I11: =vlookup(D11,'mussel-ID_key'!A:C,3,false) -> 0 | J11: 9-1-1 | L11: tross-OA-3-foot | M11: =countif(H:H,L11) -> 13
A12: 9-1-1 | B12: 1 | C12: =if(left(D12,1)="G","gallo","tross") -> gallo | D12: G01 | E12: G01-G | F12: gill | G12: =vlookup(D12,'mussel-ID_key'!A:B,2,false) -> gallo-control-0 | H12: =G12&"-"&F12 -> gallo-control-0-gill | I12: =vlookup(D12,'mussel-ID_key'!A:C,3,false) -> 0 | J12: 9-1-1 | L12: tross-OW-3-foot | M12: =countif(H:H,L12) -> 18
A13: 9-1-1 | B13: 1 | C13: =if(left(D13,1)="G","gallo","tross") -> gallo | D13: G02 | E13: G02-G | F13: gill | G13: =vlookup(D13,'mussel-ID_key'!A:B,2,false) -> gallo-control-0 | H13: =G13&"-"&F13 -> gallo-control-0-gill | I13: =vlookup(D13,'mussel-ID_key'!A:C,3,false) -> 0 | J13: 9-1-1
A14: 9-1-1 | B14: 1 | C14: =if(left(D14,1)="G","gallo","tross") -> gallo | D14: G03 | E14: G03-G | F14: gill | G14: =vlookup(D14,'mussel-ID_key'!A:B,2,false) -> gallo-control-0 | H14: =G14&"-"&F14 -> gallo-control-0-gill | I14: =vlookup(D14,'mussel-ID_key'!A:C,3,false) -> 0 | J14: 9-1-1 | L14: tross-desiccation-24h-foot | M14: =countif(H:H,L14) -> 12
A15: 9-1-1 | B15: 1 | C15: =if(left(D15,1)="G","gallo","tross") -> gallo | D15: G04 | E15: G04-G | F15: gill | G15: =vlookup(D15,'mussel-ID_key'!A:B,2,false) -> gallo-control-0 | H15: =G15&"-"&F15 -> gallo-control-0-gill | I15: =vlookup(D15,'mussel-ID_key'!A:C,3,false) -> 0 | J15: 9-1-1
A16: 9-1-1 | B16: 1 | C16: =if(left(D16,1)="G","gallo","tross") -> gallo | D16: G05 | E16: G05-G | F16: gill | G16: =vlookup(D16,'mussel-ID_key'!A:B,2,false) -> gallo-control-0 | H16: =G16&"-"&F16 -> gallo-control-0-gill | I16: =vlookup(D16,'mussel-ID_key'!A:C,3,false) -> 0 | J16: 9-1-1
A17: 9-1-1 | B17: 1 | C17: =if(left(D17,1)="G","gallo","tross") -> gallo | D17: G06 | E17: G06-G | F17: gill | G17: =vlookup(D17,'mussel-ID_key'!A:B,2,false) -> gallo-control-0 | H17: =G17&"-"&F17 -> gallo-control-0-gill | I17: =vlookup(D17,'mussel-ID_key'!A:C,3,false) -> 0 | J17: 9-1-1
A18: 9-1-1 | B18: 1 | C18: =if(left(D18,1)="G","gallo","tross") -> gallo | D18: G07 | E18: G07-G | F18: gill | G18: =vlookup(D18,'mussel-ID_key'!A:B,2,false) -> gallo-control-0 | H18: =G18&"-"&F18 -> gallo-control-0-gill | I18: =vlookup(D18,'mussel-ID_key'!A:C,3,false) -> 0 | J18: 9-1-1
A19: 9-1-1 | B19: 1 | C19: =if(left(D19,1)="G","gallo","tross") -> gallo | D19: G08 | E19: G08-G | F19: gill | G19: =vlookup(D19,'mussel-ID_key'!A:B,2,false) -> gallo-control-0 | H19: =G19&"-"&F19 -> gallo-control-0-gill | I19: =vlookup(D19,'mussel-ID_key'!A:C,3,false) -> 0 | J19: 9-1-1
A20: 9-1-1 | B20: 1 | C20: =if(left(D20,1)="G","gallo","tross") -> gallo | D20: G09 | E20: G09-G | F20: gill | G20: =vlookup(D20,'mussel-ID_key'!A:B,2,false) -> gallo-control-0 | H20: =G20&"-"&F20 -> gallo-control-0-gill | I20: =vlookup(D20,'mussel-ID_key'!A:C,3,false) -> 0 | J20: 9-1-1
A21: 9-1-1 | B21: 1 | C21: =if(left(D21,1)="G","gallo","tross") -> gallo | D21: G10 | E21: G10-G | F21: gill | G21: =vlookup(D21,'mussel-ID_key'!A:B,2,false) -> gallo-control-0 | H21: =G21&"-"&F21 -> gallo-control-0-gill | I21: =vlookup(D21,'mussel-ID_key'!A:C,3,false) -> 0 | J21: 9-1-1
A22: 9-1-1 | B22: 1 | C22: =if(left(D22,1)="G","gallo","tross") -> gallo | D22: G11 | E22: G11-G | F22: gill | G22: =vlookup(D22,'mussel-ID_key'!A:B,2,false) -> gallo-control-0 | H22: =G22&"-"&F22 -> gallo-control-0-gill | I22: =vlookup(D22,'mussel-ID_key'!A:C,3,false) -> 0 | J22: 9-1-1
A23: 9-1-1 | B23: 1 | C23: =if(left(D23,1)="G","gallo","tross") -> gallo | D23: G12 | E23: G12-G | F23: gill | G23: =vlookup(D23,'mussel-ID_key'!A:B,2,false) -> gallo-control-0 | H23: =G23&"-"&F23 -> gallo-control-0-gill | I23: =vlookup(D23,'mussel-ID_key'!A:C,3,false) -> 0 | J23: 9-1-1
A24: 9-1-1 | B24: 1 | C24: =if(left(D24,1)="G","gallo","tross") -> gallo | D24: G01 | E24: G01-M | F24: mantle | G24: =vlookup(D24,'mussel-ID_key'!A:B,2,false) -> gallo-control-0 | H24: =G24&"-"&F24 -> gallo-control-0-mantle | I24: =vlookup(D24,'mussel-ID_key'!A:C,3,false) -> 0 | J24: 9-1-1
A25: 9-1-1 | B25: 1 | C25: =if(left(D25,1)="G","gallo","tross") -> gallo | D25: G02 | E25: G02-M | F25: mantle | G25: =vlookup(D25,'mussel-ID_key'!A:B,2,false) -> gallo-control-0 | H25: =G25&"-"&F25 -> gallo-control-0-mantle | I25: =vlookup(D25,'mussel-ID_key'!A:C,3,false) -> 0 | J25: 9-1-1
A26: 9-1-1 | B26: 1 | C26: =if(left(D26,1)="G","gallo","tross") -> gallo | D26: G03 | E26: G03-M | F26: mantle | G26: =vlookup(D26,'mussel-ID_key'!A:B,2,false) -> gallo-control-0 | H26: =G26&"-"&F26 -> gallo-control-0-mantle | I26: =vlookup(D26,'mussel-ID_key'!A:C,3,false) -> 0 | J26: 9-1-1
... A35: 9-1-1 | B35: 1 | C35: =if(left(D35,1)="G","gallo","tross") -> gallo | D35: G12 | E35: G12-M | F35: mantle | G35: =vlookup(D35,'mussel-ID_key'!A:B,2,false) -> gallo-control-0 | H35: =G35&"-"&F35 -> gallo-control-0-mantle | I35: =vlookup(D35,'mussel-ID_key'!A:C,3,false) -> 0 | J35: 9-1-1
A36: 9-2-2 | B36: 7 | C36: =if(left(D36,1)="G","gallo","tross") -> gallo | D36: =left(E36,3) -> G79 | E36: G79-F | F36: foot | G36: =vlookup(D36,'mussel-ID_key'!A:B,2,false) -> gallo-control-3 | H36: =G36&"-"&F36 -> gallo-control-3-foot | I36: =vlookup(D36,'mussel-ID_key'!A:C,3,false) -> 0 | J36: 9-2-2
A37: 9-2-2 | B37: 7 | C37: =if(left(D37,1)="G","gallo","tross") -> gallo | D37: =left(E37,3) -> G80 | E37: G80-F | F37: foot | G37: =vlookup(D37,'mussel-ID_key'!A:B,2,false) -> gallo-control-3 | H37: =G37&"-"&F37 -> gallo-control-3-foot | I37: =vlookup(D37,'mussel-ID_key'!A:C,3,false) -> 0 | J37: 9-2-2
A38: 9-2-2 | B38: 7 | C38: =if(left(D38,1)="G","gallo","tross") -> gallo | D38: =left(E38,3) -> G81 | E38: G81-F | F38: foot | G38: =vlookup(D38,'mussel-ID_key'!A:B,2,false) -> gallo-control-3 | H38: =G38&"-"&F38 -> gallo-control-3-foot | I38: =vlookup(D38,'mussel-ID_key'!A:C,3,false) -> 0 | J38: 9-2-2
A39: 9-2-2 | B39: 7 | C39: =if(left(D39,1)="G","gallo","tross") -> gallo | D39: =left(E39,3) -> G82 | E39: G82-F | F39: foot | G39: =vlookup(D39,'mussel-ID_key'!A:B,2,false) -> gallo-control-3 | H39: =G39&"-"&F39 -> gallo-control-3-foot | I39: =vlookup(D39,'mussel-ID_key'!A:C,3,false) -> 0 | J39: 9-2-2
A40: 9-2-2 | B40: 7 | C40: =if(left(D40,1)="G","gallo","tross") -> gallo | D40: =left(E40,3) -> G83 | E40: G83-F | F40: foot | G40: =vlookup(D40,'mussel-ID_key'!A:B,2,false) -> gallo-control-3 | H40: =G40&"-"&F40 -> gallo-control-3-foot | I40: =vlookup(D40,'mussel-ID_key'!A:C,3,false) -> 0 | J40: 9-2-2
A41: 9-2-2 | B41: 7 | C41: =if(left(D41,1)="G","gallo","tross") -> gallo | D41: =left(E41,3) -> G84 | E41: G84-F | F41: foot | G41: =vlookup(D41,'mussel-ID_key'!A:B,2,false) -> gallo-control-3 | H41: =G41&"-"&F41 -> gallo-control-3-foot | I41: =vlookup(D41,'mussel-ID_key'!A:C,3,false) -> 0 | J41: 9-2-2
A42: 9-2-2 | B42: 7 | C42: =if(left(D42,1)="G","gallo","tross") -> gallo | D42: =left(E42,3) -> G85 | E42: G85-F | F42: foot | G42: =vlookup(D42,'mussel-ID_key'!A:B,2,false) -> gallo-control-3 | H42: =G42&"-"&F42 -> gallo-control-3-foot | I42: =vlookup(D42,'mussel-ID_key'!A:C,3,false) -> 0 | J42: 9-2-2
A43: 9-2-2 | B43: 7 | C43: =if(left(D43,1)="G","gallo","tross") -> gallo | D43: =left(E43,3) -> G86 | E43: G86-F | F43: foot | G43: =vlookup(D43,'mussel-ID_key'!A:B,2,false) -> gallo-control-3 | H43: =G43&"-"&F43 -> gallo-control-3-foot | I43: =vlookup(D43,'mussel-ID_key'!A:C,3,false) -> 0 | J43: 9-2-2
A44: 9-2-2 | B44: 7 | C44: =if(left(D44,1)="G","gallo","tross") -> gallo | D44: =left(E44,3) -> G87 | E44: G87-F | F44: foot | G44: =vlookup(D44,'mussel-ID_key'!A:B,2,false) -> gallo-control-3 | H44: =G44&"-"&F44 -> gallo-control-3-foot | I44: =vlookup(D44,'mussel-ID_key'!A:C,3,false) -> 0 | J44: 9-2-2
A45: 9-2-2 | B45: 7 | C45: =if(left(D45,1)="G","gallo","tross") -> gallo | D45: =left(E45,3) -> G88 | E45: G88-F | F45: foot | G45: =vlookup(D45,'mussel-ID_key'!A:B,2,false) -> gallo-control-3 | H45: =G45&"-"&F45 -> gallo-control-3-foot | I45: =vlookup(D45,'mussel-ID_key'!A:C,3,false) -> 0 | J45: 9-2-2
A46: 9-2-2 | B46: 7 | C46: =if(left(D46,1)="G","gallo","tross") -> gallo | D46: =left(E46,3) -> G89 | E46: G89-F | F46: foot | G46: =vlookup(D46,'mussel-ID_key'!A:B,2,false) -> gallo-control-3 | H46: =G46&"-"&F46 -> gallo-control-3-foot | I46: =vlookup(D46,'mussel-ID_key'!A:C,3,false) -> 0 | J46: 9-2-2
A47: 9-2-2 | B47: 7 | C47: =if(left(D47,1)="G","gallo","tross") -> gallo | D47: =left(E47,3) -> G90 | E47: G90-F | F47: foot | G47: =vlookup(D47,'mussel-ID_key'!A:B,2,false) -> gallo-control-3 | H47: =G47&"-"&F47 -> gallo-control-3-foot | I47: =vlookup(D47,'mussel-ID_key'!A:C,3,false) -> 0 | J47: 9-2-2
... A71: 9-2-1 | B71: 6 | C71: =if(left(D71,1)="G","gallo","tross") -> gallo | D71: =left(E71,3) -> G90 | E71: G90-M | F71: mantle | G71: =vlookup(D71,'mussel-ID_key'!A:B,2,false) -> gallo-control-3 | H71: =G71&"-"&F71 -> gallo-control-3-mantle | I71: =vlookup(D71,'mussel-ID_key'!A:C,3,false) -> 0 | J71: 9-2-1
...

Sheet mussel-ID_key
A1: ID | B1: TRT | C1: both_thread
A2: G01 | B2: gallo-control-0 | C2: 0 | E2: gallo-control-0 | F2: =countif(#REF!,E2) -> 0
A3: G02 | B3: gallo-control-0 | C3: 0 | E3: gallo-control-3 | F3: =countif(#REF!,E3) -> 0
A4: G03 | B4: gallo-control-0 | C4: 0 | E4: gallo-DO-1 | F4: =countif(#REF!,E4) -> 0
A5: G04 | B5: gallo-control-0 | C5: 0 | E5: gallo-DO-3 | F5: =countif(#REF!,E5) -> 0
A6: G05 | B6: gallo-control-0 | C6: 0 | E6: gallo-OA-1 | F6: =countif(#REF!,E6) -> 0
A7: G06 | B7: gallo-control-0 | C7: 0 | E7: gallo-OA-3 | F7: =countif(#REF!,E7) -> 0
A8: G07 | B8: gallo-control-0 | C8: 0 | E8: gallo-OW-1 | F8: =countif(#REF!,E8) -> 0
A9: G08 | B9: gallo-control-0 | C9: 0 | E9: gallo-OW-3 | F9: =countif(#REF!,E9) -> 0
A10: G09 | B10: gallo-control-0 | C10: 0 | E10: tross-control-0 | F10: =countif(#REF!,E10) -> 0
A11: G10 | B11: gallo-control-0 | C11: 0 | E11: tross-control-3 | F11: =countif(#REF!,E11) -> 0
A12: G11 | B12: gallo-control-0 | C12: 0 | E12: tross-desiccation-24h | F12: =countif(#REF!,E12) -> 0
A13: G12 | B13: gallo-control-0 | C13: 0 | E13: tross-DO-1 | F13: =countif(#REF!,E13) -> 0
... A18: T05 | B18: tross-control-0 | C18: 0 | E18: tross-OW-3 | F18: =countif(#REF!,E18) -> 0
A19: T06 | B19: tross-control-0 | C19: 0
A20: T07 | B20: tross-control-0 | C20: 0
A21: T08 | B21: tross-control-0 | C21: 0
A22: T09 | B22: tross-control-0 | C22: 0
A23: T10 | B23: tross-control-0 | C23: 0
A24: T11 | B24: tross-control-0 | C24: 0
A25: T12 | B25: tross-control-0 | C25: 0
A26: G79 | B26: gallo-control-3 | C26: 0
A27: G80 | B27: gallo-control-3 | C27: 0
A28: G81 | B28: gallo-control-3 | C28: 0
A29: G82 | B29: gallo-control-3 | C29: 0
A30: G83 | B30: gallo-control-3 | C30: 0
... A195: T42 | B195: tross-OW-3 | C195: 1
