Workbook

Sheet key
A1: ID | B1: species | C1: following | D1: trt | E1: day | F1: combo | G1: sdate | H1: L | I1: H | J1: W | K1: V | L1: thread_before | M1: thread_after | N1: thread_both | O1: thread_count_before | P1: thread_count_after
A2: G01 | B2: gallo | C2: no | D2: control | E2: 0 | F2: =B2&"-"&D2&"-"&E2 -> gallo-control-0 | G2: 44491 | H2: 62 | I2: 33 | J2: 24 | K2: =ROUND((4/3)*(H2/10)*(I2/10)*(J2/10),0) -> 65 | L2: 1 | M2: 0 | N2: =IF(L2+M2=2,1,0) -> 0 | O2: 8
A3: G02 | B3: gallo | C3: no | D3: control | E3: 0 | F3: =B3&"-"&D3&"-"&E3 -> gallo-control-0 | G3: 44491 | H3: 64 | I3: 35 | J3: 24 | K3: =ROUND((4/3)*(H3/10)*(I3/10)*(J3/10),0) -> 72 | L3: 1 | M3: 0 | N3: =IF(L3+M3=2,1,0) -> 0 | O3: 12
A4: G03 | B4: gallo | C4: no | D4: control | E4: 0 | F4: =B4&"-"&D4&"-"&E4 -> gallo-control-0 | G4: 44491 | H4: 59 | I4: 34 | J4: 23 | K4: =ROUND((4/3)*(H4/10)*(I4/10)*(J4/10),0) -> 62 | L4: 1 | M4: 0 | N4: =IF(L4+M4=2,1,0) -> 0 | O4: 6
A5: G04 | B5: gallo | C5: no | D5: control | E5: 0 | F5: =B5&"-"&D5&"-"&E5 -> gallo-control-0 | G5: 44491 | H5: 51 | I5: 30 | J5: 19 | K5: =ROUND((4/3)*(H5/10)*(I5/10)*(J5/10),0) -> 39 | L5: 1 | M5: 0 | N5: =IF(L5+M5=2,1,0) -> 0 | O5: 6
A6: G05 | B6: gallo | C6: no | D6: control | E6: 0 | F6: =B6&"-"&D6&"-"&E6 -> gallo-control-0 | G6: 44491 | H6: 63 | I6: 37 | J6: 23 | K6: =ROUND((4/3)*(H6/10)*(I6/10)*(J6/10),0) -> 71 | L6: 1 | M6: 0 | N6: =IF(L6+M6=2,1,0) -> 0 | O6: 7
A7: G06 | B7: gallo | C7: no | D7: control | E7: 0 | F7: =B7&"-"&D7&"-"&E7 -> gallo-control-0 | G7: 44491 | H7: 62 | I7: 33 | J7: 24 | K7: =ROUND((4/3)*(H7/10)*(I7/10)*(J7/10),0) -> 65 | L7: 1 | M7: 0 | N7: =IF(L7+M7=2,1,0) -> 0 | O7: 9
A8: G07 | B8: gallo | C8: no | D8: control | E8: 0 | F8: =B8&"-"&D8&"-"&E8 -> gallo-control-0 | G8: 44491 | H8: 71 | I8: 40 | J8: 25 | K8: =ROUND((4/3)*(H8/10)*(I8/10)*(J8/10),0) -> 95 | L8: 1 | M8: 0 | N8: =IF(L8+M8=2,1,0) -> 0 | O8: 12
A9: G08 | B9: gallo | C9: no | D9: control | E9: 0 | F9: =B9&"-"&D9&"-"&E9 -> gallo-control-0 | G9: 44491 | H9: 67 | I9: 34 | J9: 24 | K9: =ROUND((4/3)*(H9/10)*(I9/10)*(J9/10),0) -> 73 | L9: 1 | M9: 0 | N9: =IF(L9+M9=2,1,0) -> 0 | O9: 14
A10: G09 | B10: gallo | C10: no | D10: control | E10: 0 | F10: =B10&"-"&D10&"-"&E10 -> gallo-control-0 | G10: 44491 | H10: 58 | I10: 32 | J10: 23 | K10: =ROUND((4/3)*(H10/10)*(I10/10)*(J10/10),0) -> 57 | L10: 1 | M10: 0 | N10: =IF(L10+M10=2,1,0) -> 0 | O10: 11
A11: G10 | B11: gallo | C11: no | D11: control | E11: 0 | F11: =B11&"-"&D11&"-"&E11 -> gallo-control-0 | G11: 44491 | H11: 67 | I11: 34 | J11: 24 | K11: =ROUND((4/3)*(H11/10)*(I11/10)*(J11/10),0) -> 73 | L11: 1 | M11: 0 | N11: =IF(L11+M11=2,1,0) -> 0 | O11: 7
A12: G11 | B12: gallo | C12: no | D12: control | E12: 0 | F12: =B12&"-"&D12&"-"&E12 -> gallo-control-0 | G12: 44491 | H12: 63 | I12: 34 | J12: 20 | K12: =ROUND((4/3)*(H12/10)*(I12/10)*(J12/10),0) -> 57 | L12: 1 | M12: 0 | N12: =IF(L12+M12=2,1,0) -> 0 | O12: 9
A13: G12 | B13: gallo | C13: no | D13: control | E13: 0 | F13: =B13&"-"&D13&"-"&E13 -> gallo-control-0 | G13: 44491 | H13: 65 | I13: 36 | J13: 23 | K13: =ROUND((4/3)*(H13/10)*(I13/10)*(J13/10),0) -> 72 | L13: 1 | M13: 0 | N13: =IF(L13+M13=2,1,0) -> 0 | O13: 13
... A25: T12 | B25: tross | C25: no | D25: control | E25: 0 | F25: =B25&"-"&D25&"-"&E25 -> tross-control-0 | G25: 44491 | H25: 63 | I25: 30 | J25: 21 | K25: =ROUND((4/3)*(H25/10)*(I25/10)*(J25/10),0) -> 53 | L25: 1 | M25: 0 | N25: =IF(L25+M25=2,1,0) -> 0 | O25: 8
A26: G79 | B26: gallo | C26: no | D26: control | E26: 3 | F26: =B26&"-"&D26&"-"&E26 -> gallo-control-3 | G26: 44498 | H26: 61 | I26: 35 | J26: 22 | K26: =ROUND((4/3)*(H26/10)*(I26/10)*(J26/10),0) -> 63 | L26: 0 | M26: 1 | N26: =IF(L26+M26=2,1,0) -> 0 | P26: 9
A27: G80 | B27: gallo | C27: no | D27: control | E27: 3 | F27: =B27&"-"&D27&"-"&E27 -> gallo-control-3 | G27: 44498 | H27: 68 | I27: 39 | J27: 24 | K27: =ROUND((4/3)*(H27/10)*(I27/10)*(J27/10),0) -> 85 | L27: 0 | M27: 1 | N27: =IF(L27+M27=2,1,0) -> 0 | P27: 13
A28: G81 | B28: gallo | C28: no | D28: control | E28: 3 | F28: =B28&"-"&D28&"-"&E28 -> gallo-control-3 | G28: 44498 | H28: 60 | I28: 30 | J28: 23 | K28: =ROUND((4/3)*(H28/10)*(I28/10)*(J28/10),0) -> 55 | L28: 0 | M28: 1 | N28: =IF(L28+M28=2,1,0) -> 0 | P28: 12
A29: G82 | B29: gallo | C29: no | D29: control | E29: 3 | F29: =B29&"-"&D29&"-"&E29 -> gallo-control-3 | G29: 44498 | H29: 66 | I29: 39 | J29: 23 | K29: =ROUND((4/3)*(H29/10)*(I29/10)*(J29/10),0) -> 79 | L29: 0 | M29: 1 | N29: =IF(L29+M29=2,1,0) -> 0 | P29: 17
A30: G83 | B30: gallo | C30: no | D30: control | E30: 3 | F30: =B30&"-"&D30&"-"&E30 -> gallo-control-3 | G30: 44498 | H30: 59 | I30: 35 | J30: 21 | K30: =ROUND((4/3)*(H30/10)*(I30/10)*(J30/10),0) -> 58 | L30: 0 | M30: 1 | N30: =IF(L30+M30=2,1,0) -> 0 | P30: 7
A31: G84 | B31: gallo | C31: no | D31: control | E31: 3 | F31: =B31&"-"&D31&"-"&E31 -> gallo-control-3 | G31: 44498 | H31: 72 | I31: 37 | J31: 26 | K31: =ROUND((4/3)*(H31/10)*(I31/10)*(J31/10),0) -> 92 | L31: 0 | M31: 1 | N31: =IF(L31+M31=2,1,0) -> 0 | P31: 11
A32: G85 | B32: gallo | C32: no | D32: control | E32: 3 | F32: =B32&"-"&D32&"-"&E32 -> gallo-control-3 | G32: 44498 | H32: 68 | I32: 39 | J32: 25 | K32: =ROUND((4/3)*(H32/10)*(I32/10)*(J32/10),0) -> 88 | L32: 0 | M32: 1 | N32: =IF(L32+M32=2,1,0) -> 0 | P32: 8
A33: G86 | B33: gallo | C33: no | D33: control | E33: 3 | F33: =B33&"-"&D33&"-"&E33 -> gallo-control-3 | G33: 44498 | H33: 62 | I33: 30 | J33: 23 | K33: =ROUND((4/3)*(H33/10)*(I33/10)*(J33/10),0) -> 57 | L33: 0 | M33: 1 | N33: =IF(L33+M33=2,1,0) -> 0 | P33: 11
A34: G87 | B34: gallo | C34: no | D34: control | E34: 3 | F34: =B34&"-"&D34&"-"&E34 -> gallo-control-3 | G34: 44498 | H34: 68 | I34: 38 | J34: 27 | K34: =ROUND((4/3)*(H34/10)*(I34/10)*(J34/10),0) -> 93 | L34: 0 | M34: 1 | N34: =IF(L34+M34=2,1,0) -> 0 | P34: 26
A35: G88 | B35: gallo | C35: no | D35: control | E35: 3 | F35: =B35&"-"&D35&"-"&E35 -> gallo-control-3 | G35: 44498 | H35: 71 | I35: 36 | J35: 25 | K35: =ROUND((4/3)*(H35/10)*(I35/10)*(J35/10),0) -> 85 | L35: 0 | M35: 1 | N35: =IF(L35+M35=2,1,0) -> 0 | P35: 5
A36: G89 | B36: gallo | C36: no | D36: control | E36: 3 | F36: =B36&"-"&D36&"-"&E36 -> gallo-control-3 | G36: 44498 | H36: 51 | I36: 27 | J36: 19 | K36: =ROUND((4/3)*(H36/10)*(I36/10)*(J36/10),0) -> 35 | L36: 0 | M36: 0 | N36: =IF(L36+M36=2,1,0) -> 0
A37: G90 | B37: gallo | C37: no | D37: control | E37: 3 | F37: =B37&"-"&D37&"-"&E37 -> gallo-control-3 | G37: 44498 | H37: 48 | I37: 23 | J37: 16 | K37: =ROUND((4/3)*(H37/10)*(I37/10)*(J37/10),0) -> 24 | L37: 0 | M37: 0 | N37: =IF(L37+M37=2,1,0) -> 0
A38: T126 | B38: tross | C38: no | D38: control | E38: 3 | F38: =B38&"-"&D38&"-"&E38 -> tross-control-3 | G38: 44498 | H38: 61 | I38: 26 | J38: 20 | K38: =ROUND((4/3)*(H38/10)*(I38/10)*(J38/10),0) -> 42 | L38: 0 | M38: 1 | N38: =IF(L38+M38=2,1,0) -> 0 | P38: 12
A39: T127 | B39: tross | C39: no | D39: control | E39: 3 | F39: =B39&"-"&D39&"-"&E39 -> tross-control-3 | G39: 44498 | H39: 60 | I39: 27 | J39: 20 | K39: =ROUND((4/3)*(H39/10)*(I39/10)*(J39/10),0) -> 43 | L39: 0 | M39: 1 | N39: =IF(L39+M39=2,1,0) -> 0 | P39: 2
A40: T128 | B40: tross | C40: no | D40: control | E40: 3 | F40: =B40&"-"&D40&"-"&E40 -> tross-control-3 | G40: 44498 | H40: 63 | I40: 28 | J40: 22 | K40: =ROUND((4/3)*(H40/10)*(I40/10)*(J40/10),0) -> 52 | L40: 0 | M40: 1 | N40: =IF(L40+M40=2,1,0) -> 0 | P40: 21
A41: T129 | B41: tross | C41: no | D41: control | E41: 3 | F41: =B41&"-"&D41&"-"&E41 -> tross-control-3 | G41: 44498 | H41: 60 | I41: 28 | J41: 20 | K41: =ROUND((4/3)*(H41/10)*(I41/10)*(J41/10),0) -> 45 | L41: 0 | M41: 1 | N41: =IF(L41+M41=2,1,0) -> 0 | P41: 7
A42: T130 | B42: tross | C42: no | D42: control | E42: 3 | F42: =B42&"-"&D42&"-"&E42 -> tross-control-3 | G42: 44498 | H42: 54 | I42: 25 | J42: 16 | K42: =ROUND((4/3)*(H42/10)*(I42/10)*(J42/10),0) -> 29 | L42: 0 | M42: 1 | N42: =IF(L42+M42=2,1,0) -> 0 | P42: 7
A43: T131 | B43: tross | C43: no | D43: control | E43: 3 | F43: =B43&"-"&D43&"-"&E43 -> tross-control-3 | G43: 44498 | H43: 61 | I43: 28 | J43: 20 | K43: =ROUND((4/3)*(H43/10)*(I43/10)*(J43/10),0) -> 46 | L43: 0 | M43: 1 | N43: =IF(L43+M43=2,1,0) -> 0 | P43: 6
A44: T132 | B44: tross | C44: no | D44: control | E44: 3 | F44: =B44&"-"&D44&"-"&E44 -> tross-control-3 | G44: 44498 | H44: 53 | I44: 25 | J44: 18 | K44: =ROUND((4/3)*(H44/10)*(I44/10)*(J44/10),0) -> 32 | L44: 0 | M44: 1 | N44: =IF(L44+M44=2,1,0) -> 0 | P44: 2
A45: T133 | B45: tross | C45: no | D45: control | E45: 3 | F45: =B45&"-"&D45&"-"&E45 -> tross-control-3 | G45: 44498 | H45: 55 | I45: 26 | J45: 19 | K45: =ROUND((4/3)*(H45/10)*(I45/10)*(J45/10),0) -> 36 | L45: 0 | M45: 1 | N45: =IF(L45+M45=2,1,0) -> 0 | P45: 1
A46: T134 | B46: tross | C46: no | D46: control | E46: 3 | F46: =B46&"-"&D46&"-"&E46 -> tross-control-3 | G46: 44498 | H46: 65 | I46: 28 | J46: 22 | K46: =ROUND((4/3)*(H46/10)*(I46/10)*(J46/10),0) -> 53 | L46: 0 | M46: 1 | N46: =IF(L46+M46=2,1,0) -> 0 | P46: 8
A47: T135 | B47: tross | C47: no | D47: control | E47: 3 | F47: =B47&"-"&D47&"-"&E47 -> tross-control-3 | G47: 44498 | H47: 64 | I47: 30 | J47: 24 | K47: =ROUND((4/3)*(H47/10)*(I47/10)*(J47/10),0) -> 61 | L47: 0 | M47: 1 | N47: =IF(L47+M47=2,1,0) -> 0 | P47: 5
A48: T136 | B48: tross | C48: no | D48: control | E48: 3 | F48: =B48&"-"&D48&"-"&E48 -> tross-control-3 | G48: 44498 | H48: 59 | I48: 26 | J48: 20 | K48: =ROUND((4/3)*(H48/10)*(I48/10)*(J48/10),0) -> 41 | L48: 0 | M48: 0 | N48: =IF(L48+M48=2,1,0) -> 0
A49: T137 | B49: tross | C49: no | D49: control | E49: 3 | F49: =B49&"-"&D49&"-"&E49 -> tross-control-3 | G49: 44498 | H49: 56 | I49: 25 | J49: 21 | K49: =ROUND((4/3)*(H49/10)*(I49/10)*(J49/10),0) -> 39 | L49: 0 | M49: 0 | N49: =IF(L49+M49=2,1,0) -> 0
A50: T138 | B50: tross | C50: no | D50: desiccation | E50: 24h | F50: =B50&"-"&D50&"-"&E50 -> tross-desiccation-24h | G50: 44501 | H50: 59 | I50: 26 | J50: 19 | K50: =ROUND((4/3)*(H50/10)*(I50/10)*(J50/10),0) -> 39 | L50: 0 | M50: 0 | N50: =IF(L50+M50=2,1,0) -> 0
A51: T139 | B51: tross | C51: no | D51: desiccation | E51: 24h | F51: =B51&"-"&D51&"-"&E51 -> tross-desiccation-24h | G51: 44501 | H51: 60 | I51: 28 | J51: 20 | K51: =ROUND((4/3)*(H51/10)*(I51/10)*(J51/10),0) -> 45 | L51: 0 | M51: 0 | N51: =IF(L51+M51=2,1,0) -> 0
...

Sheet tissue-for-RNA
A1: ID | B1: trt | C1: day | D1: species | E1: day | F1: priority
A2: T46 | B2: =VLOOKUP(A2,key!A:F,4,FALSE) -> DO | C2: =VLOOKUP(A2,key!A:F,5,FALSE) -> 3 | D2: tross | E2: 3 | F2: high
A3: T47 | B3: =VLOOKUP(A3,key!A:F,4,FALSE) -> DO | C3: =VLOOKUP(A3,key!A:F,5,FALSE) -> 3 | D3: tross | E3: 3 | F3: high
A4: T49 | B4: =VLOOKUP(A4,key!A:F,4,FALSE) -> DO | C4: =VLOOKUP(A4,key!A:F,5,FALSE) -> 3 | D4: tross | E4: 3 | F4: high
A5: T51 | B5: =VLOOKUP(A5,key!A:F,4,FALSE) -> DO | C5: =VLOOKUP(A5,key!A:F,5,FALSE) -> 3 | D5: tross | E5: 3 | F5: high
A6: T52 | B6: =VLOOKUP(A6,key!A:F,4,FALSE) -> DO | C6: =VLOOKUP(A6,key!A:F,5,FALSE) -> 3 | D6: tross | E6: 3 | F6: high
A7: T55 | B7: =VLOOKUP(A7,key!A:F,4,FALSE) -> DO | C7: =VLOOKUP(A7,key!A:F,5,FALSE) -> 3 | D7: tross | E7: 3 | F7: high
A8: T56 | B8: =VLOOKUP(A8,key!A:F,4,FALSE) -> DO | C8: =VLOOKUP(A8,key!A:F,5,FALSE) -> 3 | D8: tross | E8: 3 | F8: high
A9: T57 | B9: =VLOOKUP(A9,key!A:F,4,FALSE) -> DO | C9: =VLOOKUP(A9,key!A:F,5,FALSE) -> 3 | D9: tross | E9: 3 | F9: high
A10: T58 | B10: =VLOOKUP(A10,key!A:F,4,FALSE) -> DO | C10: =VLOOKUP(A10,key!A:F,5,FALSE) -> 3 | D10: tross | E10: 3 | F10: high
A11: G13 | B11: =VLOOKUP(A11,key!A:F,4,FALSE) -> OA | C11: =VLOOKUP(A11,key!A:F,5,FALSE) -> 3 | D11: gallo | E11: 3 | F11: high
A12: G14 | B12: =VLOOKUP(A12,key!A:F,4,FALSE) -> OA | C12: =VLOOKUP(A12,key!A:F,5,FALSE) -> 3 | D12: gallo | E12: 3 | F12: high
A13: G15 | B13: =VLOOKUP(A13,key!A:F,4,FALSE) -> OA | C13: =VLOOKUP(A13,key!A:F,5,FALSE) -> 3 | D13: gallo | E13: 3 | F13: high
... A66: T12 | B66: =VLOOKUP(A66,key!A:F,4,FALSE) -> control | C66: =VLOOKUP(A66,key!A:F,5,FALSE) -> 0 | D66: tross | E66: 0 | F66: high
A67: T138 | B67: =VLOOKUP(A67,key!A:F,4,FALSE) -> desiccation | C67: =VLOOKUP(A67,key!A:F,5,FALSE) -> 24h | D67: tross | E67: 24h | F67: low
A68: T139 | B68: =VLOOKUP(A68,key!A:F,4,FALSE) -> desiccation | C68: =VLOOKUP(A68,key!A:F,5,FALSE) -> 24h | D68: tross | E68: 24h | F68: low
A69: T140 | B69: =VLOOKUP(A69,key!A:F,4,FALSE) -> desiccation | C69: =VLOOKUP(A69,key!A:F,5,FALSE) -> 24h | D69: tross | E69: 24h | F69: low
A70: T141 | B70: =VLOOKUP(A70,key!A:F,4,FALSE) -> desiccation | C70: =VLOOKUP(A70,key!A:F,5,FALSE) -> 24h | D70: tross | E70: 24h | F70: low
A71: T142 | B71: =VLOOKUP(A71,key!A:F,4,FALSE) -> desiccation | C71: =VLOOKUP(A71,key!A:F,5,FALSE) -> 24h | D71: tross | E71: 24h | F71: low
A72: T143 | B72: =VLOOKUP(A72,key!A:F,4,FALSE) -> desiccation | C72: =VLOOKUP(A72,key!A:F,5,FALSE) -> 24h | D72: tross | E72: 24h | F72: low
A73: T144 | B73: =VLOOKUP(A73,key!A:F,4,FALSE) -> desiccation | C73: =VLOOKUP(A73,key!A:F,5,FALSE) -> 24h | D73: tross | E73: 24h | F73: low
A74: T145 | B74: =VLOOKUP(A74,key!A:F,4,FALSE) -> desiccation | C74: =VLOOKUP(A74,key!A:F,5,FALSE) -> 24h | D74: tross | E74: 24h | F74: low
A75: T146 | B75: =VLOOKUP(A75,key!A:F,4,FALSE) -> desiccation | C75: =VLOOKUP(A75,key!A:F,5,FALSE) -> 24h | D75: tross | E75: 24h | F75: low
A76: T147 | B76: =VLOOKUP(A76,key!A:F,4,FALSE) -> desiccation | C76: =VLOOKUP(A76,key!A:F,5,FALSE) -> 24h | D76: tross | E76: 24h | F76: low
A77: T148 | B77: =VLOOKUP(A77,key!A:F,4,FALSE) -> desiccation | C77: =VLOOKUP(A77,key!A:F,5,FALSE) -> 24h | D77: tross | E77: 24h | F77: low
A78: T149 | B78: =VLOOKUP(A78,key!A:F,4,FALSE) -> desiccation | C78: =VLOOKUP(A78,key!A:F,5,FALSE) -> 24h | D78: tross | E78: 24h | F78: low
A79: G79 | B79: =VLOOKUP(A79,key!A:F,4,FALSE) -> control | C79: =VLOOKUP(A79,key!A:F,5,FALSE) -> 3 | D79: gallo | E79: 3 | F79: medium
A80: G80 | B80: =VLOOKUP(A80,key!A:F,4,FALSE) -> control | C80: =VLOOKUP(A80,key!A:F,5,FALSE) -> 3 | D80: gallo | E80: 3 | F80: medium
A81: G81 | B81: =VLOOKUP(A81,key!A:F,4,FALSE) -> control | C81: =VLOOKUP(A81,key!A:F,5,FALSE) -> 3 | D81: gallo | E81: 3 | F81: medium
A82: G82 | B82: =VLOOKUP(A82,key!A:F,4,FALSE) -> control | C82: =VLOOKUP(A82,key!A:F,5,FALSE) -> 3 | D82: gallo | E82: 3 | F82: medium
A83: G83 | B83: =VLOOKUP(A83,key!A:F,4,FALSE) -> control | C83: =VLOOKUP(A83,key!A:F,5,FALSE) -> 3 | D83: gallo | E83: 3 | F83: medium
A84: G84 | B84: =VLOOKUP(A84,key!A:F,4,FALSE) -> control | C84: =VLOOKUP(A84,key!A:F,5,FALSE) -> 3 | D84: gallo | E84: 3 | F84: medium
A85: G85 | B85: =VLOOKUP(A85,key!A:F,4,FALSE) -> control | C85: =VLOOKUP(A85,key!A:F,5,FALSE) -> 3 | D85: gallo | E85: 3 | F85: medium
A86: G86 | B86: =VLOOKUP(A86,key!A:F,4,FALSE) -> control | C86: =VLOOKUP(A86,key!A:F,5,FALSE) -> 3 | D86: gallo | E86: 3 | F86: medium
A87: G87 | B87: =VLOOKUP(A87,key!A:F,4,FALSE) -> control | C87: =VLOOKUP(A87,key!A:F,5,FALSE) -> 3 | D87: gallo | E87: 3 | F87: medium
A88: G88 | B88: =VLOOKUP(A88,key!A:F,4,FALSE) -> control | C88: =VLOOKUP(A88,key!A:F,5,FALSE) -> 3 | D88: gallo | E88: 3 | F88: medium
A89: T126 | B89: =VLOOKUP(A89,key!A:F,4,FALSE) -> control | C89: =VLOOKUP(A89,key!A:F,5,FALSE) -> 3 | D89: tross | E89: 3 | F89: medium
A90: T127 | B90: =VLOOKUP(A90,key!A:F,4,FALSE) -> control | C90: =VLOOKUP(A90,key!A:F,5,FALSE) -> 3 | D90: tross | E90: 3 | F90: medium
... A126: T111 | B126: =VLOOKUP(A126,key!A:F,4,FALSE) -> DO | C126: =VLOOKUP(A126,key!A:F,5,FALSE) -> 3 | D126: tross | E126: 3 | F126: medium

Sheet rna_isolation_info
A1: species | B1: sample | C1: mussel | D1: tissue | E1: tissue_name | F1: treatment | G1: day | H1: paired_threads | I1: concentration(ng/uL) | J1: volume(uL) | K1: yield(ng) | L1: isolation_date | M1: storage_location | N1: quant_method | O1: DNased(y/n)
A2: M.trossulus | B2: T01-F | C2: T01 | D2: F | E2: foot | F2: =VLOOKUP(C2,key!A:P,4,FALSE) -> control | G2: =VLOOKUP(C2,key!A:P,5,FALSE) -> 0 | H2: =VLOOKUP(C2,key!A:N,14,FALSE) -> 0 | I2: 122 | J2: 200 | K2: =I2*J2 -> 24400 | L2: =HYPERLINK("https://robertslab.github.io/sams-notebook/2021/12/22/RNA-Isolation-M.trossulus-Foot-and-Phenol-Gland.html", "20211222") -> 20211222 | M2: =HYPERLINK("https://docs.google.com/spreadsheets/d/1jL9gOqtcHrm8JPUtZ5KShpX7_olFuci_5Gq7xqgZKIM/edit?usp=sharing", "Sam's RNA Box #2") -> Sam's RNA Box #2 | N2: Qubit RNA HS assay | O2: y
A3: M.trossulus | B3: T02-F | C3: T02 | D3: F | E3: foot | F3: =VLOOKUP(C3,key!A:P,4,FALSE) -> control | G3: =VLOOKUP(C3,key!A:P,5,FALSE) -> 0 | H3: =VLOOKUP(C3,key!A:N,14,FALSE) -> 0 | I3: 166 | J3: 50 | K3: =I3*J3 -> 8300 | L3: =HYPERLINK("https://robertslab.github.io/sams-notebook/2021/12/22/RNA-Isolation-M.trossulus-Foot-and-Phenol-Gland.html", "20211222") -> 20211222 | M3: =HYPERLINK("https://docs.google.com/spreadsheets/d/1jL9gOqtcHrm8JPUtZ5KShpX7_olFuci_5Gq7xqgZKIM/edit?usp=sharing", "Sam's RNA Box #2") -> Sam's RNA Box #2 | N3: Qubit RNA HS assay | O3: y
A4: M.trossulus | B4: T03-F | C4: T03 | D4: F | E4: foot | F4: =VLOOKUP(C4,key!A:P,4,FALSE) -> control | G4: =VLOOKUP(C4,key!A:P,5,FALSE) -> 0 | H4: =VLOOKUP(C4,key!A:N,14,FALSE) -> 0 | I4: 186 | J4: 50 | K4: =I4*J4 -> 9300 | L4: =HYPERLINK("https://robertslab.github.io/sams-notebook/2021/12/22/RNA-Isolation-M.trossulus-Foot-and-Phenol-Gland.html", "20211222") -> 20211222 | M4: =HYPERLINK("https://docs.google.com/spreadsheets/d/1jL9gOqtcHrm8JPUtZ5KShpX7_olFuci_5Gq7xqgZKIM/edit?usp=sharing", "Sam's RNA Box #2") -> Sam's RNA Box #2 | N4: Qubit RNA HS assay | O4: y
A5: M.trossulus | B5: T04-F | C5: T04 | D5: F | E5: foot | F5: =VLOOKUP(C5,key!A:P,4,FALSE) -> control | G5: =VLOOKUP(C5,key!A:P,5,FALSE) -> 0 | H5: =VLOOKUP(C5,key!A:N,14,FALSE) -> 0 | I5: 138 | J5: 200 | K5: =I5*J5 -> 27600 | L5: =HYPERLINK("https://robertslab.github.io/sams-notebook/2021/12/22/RNA-Isolation-M.trossulus-Foot-and-Phenol-Gland.html", "20211222") -> 20211222 | M5: =HYPERLINK("https://docs.google.com/spreadsheets/d/1jL9gOqtcHrm8JPUtZ5KShpX7_olFuci_5Gq7xqgZKIM/edit?usp=sharing", "Sam's RNA Box #2") -> Sam's RNA Box #2 | N5: Qubit RNA HS assay | O5: y
A6: M.trossulus | B6: T05-F | C6: T05 | D6: F | E6: foot | F6: =VLOOKUP(C6,key!A:P,4,FALSE) -> control | G6: =VLOOKUP(C6,key!A:P,5,FALSE) -> 0 | H6: =VLOOKUP(C6,key!A:N,14,FALSE) -> 0 | I6: 136 | J6: 200 | K6: =I6*J6 -> 27200 | L6: =HYPERLINK("https://robertslab.github.io/sams-notebook/2021/12/22/RNA-Isolation-M.trossulus-Foot-and-Phenol-Gland.html", "20211222") -> 20211222 | M6: =HYPERLINK("https://docs.google.com/spreadsheets/d/1jL9gOqtcHrm8JPUtZ5KShpX7_olFuci_5Gq7xqgZKIM/edit?usp=sharing", "Sam's RNA Box #2") -> Sam's RNA Box #2 | N6: Qubit RNA HS assay | O6: y
A7: M.trossulus | B7: T06-F | C7: T06 | D7: F | E7: foot | F7: =VLOOKUP(C7,key!A:P,4,FALSE) -> control | G7: =VLOOKUP(C7,key!A:P,5,FALSE) -> 0 | H7: =VLOOKUP(C7,key!A:N,14,FALSE) -> 0 | I7: 106 | J7: 400 | K7: =I7*J7 -> 42400 | L7: =HYPERLINK("https://robertslab.github.io/sams-notebook/2021/12/22/RNA-Isolation-M.trossulus-Foot-and-Phenol-Gland.html", "20211222") -> 20211222 | M7: =HYPERLINK("https://docs.google.com/spreadsheets/d/1jL9gOqtcHrm8JPUtZ5KShpX7_olFuci_5Gq7xqgZKIM/edit?usp=sharing", "Sam's RNA Box #2") -> Sam's RNA Box #2 | N7: Qubit RNA HS assay | O7: y
A8: M.trossulus | B8: T07-F | C8: T07 | D8: F | E8: foot | F8: =VLOOKUP(C8,key!A:P,4,FALSE) -> control | G8: =VLOOKUP(C8,key!A:P,5,FALSE) -> 0 | H8: =VLOOKUP(C8,key!A:N,14,FALSE) -> 0 | I8: 27.6 | J8: 50 | K8: =I8*J8 -> 1380 | L8: =HYPERLINK("https://robertslab.github.io/sams-notebook/2021/12/22/RNA-Isolation-M.trossulus-Foot-and-Phenol-Gland.html", "20211222") -> 20211222 | M8: =HYPERLINK("https://docs.google.com/spreadsheets/d/1jL9gOqtcHrm8JPUtZ5KShpX7_olFuci_5Gq7xqgZKIM/edit?usp=sharing", "Sam's RNA Box #2") -> Sam's RNA Box #2 | N8: Qubit RNA HS assay | O8: y
A9: M.trossulus | B9: T08-F | C9: T08 | D9: F | E9: foot | F9: =VLOOKUP(C9,key!A:P,4,FALSE) -> control | G9: =VLOOKUP(C9,key!A:P,5,FALSE) -> 0 | H9: =VLOOKUP(C9,key!A:N,14,FALSE) -> 0 | I9: 172 | J9: 100 | K9: =I9*J9 -> 17200 | L9: =HYPERLINK("https://robertslab.github.io/sams-notebook/2021/12/22/RNA-Isolation-M.trossulus-Foot-and-Phenol-Gland.html", "20211222") -> 20211222 | M9: =HYPERLINK("https://docs.google.com/spreadsheets/d/1jL9gOqtcHrm8JPUtZ5KShpX7_olFuci_5Gq7xqgZKIM/edit?usp=sharing", "Sam's RNA Box #2") -> Sam's RNA Box #2 | N9: Qubit RNA HS assay | O9: y
A10: M.trossulus | B10: T09-F | C10: T09 | D10: F | E10: foot | F10: =VLOOKUP(C10,key!A:P,4,FALSE) -> control | G10: =VLOOKUP(C10,key!A:P,5,FALSE) -> 0 | H10: =VLOOKUP(C10,key!A:N,14,FALSE) -> 0 | I10: 174 | J10: 200 | K10: =I10*J10 -> 34800 | L10: =HYPERLINK("https://robertslab.github.io/sams-notebook/2021/12/22/RNA-Isolation-M.trossulus-Foot-and-Phenol-Gland.html", "20211222") -> 20211222 | M10: =HYPERLINK("https://docs.google.com/spreadsheets/d/1jL9gOqtcHrm8JPUtZ5KShpX7_olFuci_5Gq7xqgZKIM/edit?usp=sharing", "Sam's RNA Box #2") -> Sam's RNA Box #2 | N10: Qubit RNA HS assay | O10: y
A11: M.trossulus | B11: T10-F | C11: T10 | D11: F | E11: foot | F11: =VLOOKUP(C11,key!A:P,4,FALSE) -> control | G11: =VLOOKUP(C11,key!A:P,5,FALSE) -> 0 | H11: =VLOOKUP(C11,key!A:N,14,FALSE) -> 0 | I11: 188 | J11: 50 | K11: =I11*J11 -> 9400 | L11: =HYPERLINK("https://robertslab.github.io/sams-notebook/2021/12/22/RNA-Isolation-M.trossulus-Foot-and-Phenol-Gland.html", "20211222") -> 20211222 | M11: =HYPERLINK("https://docs.google.com/spreadsheets/d/1jL9gOqtcHrm8JPUtZ5KShpX7_olFuci_5Gq7xqgZKIM/edit?usp=sharing", "Sam's RNA Box #2") -> Sam's RNA Box #2 | N11: Qubit RNA HS assay | O11: y
A12: M.trossulus | B12: T11-F | C12: T11 | D12: F | E12: foot | F12: =VLOOKUP(C12,key!A:P,4,FALSE) -> control | G12: =VLOOKUP(C12,key!A:P,5,FALSE) -> 0 | H12: =VLOOKUP(C12,key!A:N,14,FALSE) -> 0 | I12: 116 | J12: 200 | K12: =I12*J12 -> 23200 | L12: =HYPERLINK("https://robertslab.github.io/sams-notebook/2021/12/22/RNA-Isolation-M.trossulus-Foot-and-Phenol-Gland.html", "20211222") -> 20211222 | M12: =HYPERLINK("https://docs.google.com/spreadsheets/d/1jL9gOqtcHrm8JPUtZ5KShpX7_olFuci_5Gq7xqgZKIM/edit?usp=sharing", "Sam's RNA Box #2") -> Sam's RNA Box #2 | N12: Qubit RNA HS assay | O12: y
A13: M.trossulus | B13: T12-F | C13: T12 | D13: F | E13: foot | F13: =VLOOKUP(C13,key!A:P,4,FALSE) -> control | G13: =VLOOKUP(C13,key!A:P,5,FALSE) -> 0 | H13: =VLOOKUP(C13,key!A:N,14,FALSE) -> 0 | I13: 132 | J13: 200 | K13: =I13*J13 -> 26400 | L13: =HYPERLINK("https://robertslab.github.io/sams-notebook/2021/12/22/RNA-Isolation-M.trossulus-Foot-and-Phenol-Gland.html", "20211222") -> 20211222 | M13: =HYPERLINK("https://docs.google.com/spreadsheets/d/1jL9gOqtcHrm8JPUtZ5KShpX7_olFuci_5Gq7xqgZKIM/edit?usp=sharing", "Sam's RNA Box #2") -> Sam's RNA Box #2 | N13: Qubit RNA HS assay | O13: y
... A25: M.trossulus | B25: T12-F_PG | C25: T12 | D25: F_PG | E25: phenol gland | F25: =VLOOKUP(C25,key!A:P,4,FALSE) -> control | G25: =VLOOKUP(C25,key!A:P,5,FALSE) -> 0 | H25: =VLOOKUP(C25,key!A:N,14,FALSE) -> 0 | I25: 152 | J25: 50 | K25: =I25*J25 -> 7600 | L25: =HYPERLINK("https://robertslab.github.io/sams-notebook/2021/12/22/RNA-Isolation-M.trossulus-Foot-and-Phenol-Gland.html", "20211222") -> 20211222 | M25: =HYPERLINK("https://docs.google.com/spreadsheets/d/1jL9gOqtcHrm8JPUtZ5KShpX7_olFuci_5Gq7xqgZKIM/edit?usp=sharing", "Sam's RNA Box #2") -> Sam's RNA Box #2 | N25: Qubit RNA HS assay | O25: y
A26: M.trossulus | B26: T01-G | C26: T01 | D26: G | E26: gill | F26: =VLOOKUP(C26,key!A:P,4,FALSE) -> control | G26: =VLOOKUP(C26,key!A:P,5,FALSE) -> 0 | H26: =VLOOKUP(C26,key!A:N,14,FALSE) -> 0 | I26: 28 | J26: 100 | K26: =I26*J26 -> 2800 | L26: =HYPERLINK("https://robertslab.github.io/sams-notebook/2021/12/23/RNA-Isolation-M.trossulus-Phenol-Gland-and-Gill.html", "20211223") -> 20211223 | M26: =HYPERLINK("https://docs.google.com/spreadsheets/d/1jL9gOqtcHrm8JPUtZ5KShpX7_olFuci_5Gq7xqgZKIM/edit?usp=sharing", "Sam's RNA Box #2") -> Sam's RNA Box #2 | N26: Qubit RNA HS assay | O26: y
A27: M.trossulus | B27: T02-G | C27: T02 | D27: G | E27: gill | F27: =VLOOKUP(C27,key!A:P,4,FALSE) -> control | G27: =VLOOKUP(C27,key!A:P,5,FALSE) -> 0 | H27: =VLOOKUP(C27,key!A:N,14,FALSE) -> 0 | I27: 148 | J27: 100 | K27: =I27*J27 -> 14800 | L27: =HYPERLINK("https://robertslab.github.io/sams-notebook/2021/12/23/RNA-Isolation-M.trossulus-Phenol-Gland-and-Gill.html", "20211223") -> 20211223 | M27: =HYPERLINK("https://docs.google.com/spreadsheets/d/1jL9gOqtcHrm8JPUtZ5KShpX7_olFuci_5Gq7xqgZKIM/edit?usp=sharing", "Sam's RNA Box #2") -> Sam's RNA Box #2 | N27: Qubit RNA HS assay | O27: y
A28: M.trossulus | B28: T03-G | C28: T03 | D28: G | E28: gill | F28: =VLOOKUP(C28,key!A:P,4,FALSE) -> control | G28: =VLOOKUP(C28,key!A:P,5,FALSE) -> 0 | H28: =VLOOKUP(C28,key!A:N,14,FALSE) -> 0 | I28: 65.4 | J28: 100 | K28: =I28*J28 -> 6540 | L28: =HYPERLINK("https://robertslab.github.io/sams-notebook/2021/12/23/RNA-Isolation-M.trossulus-Phenol-Gland-and-Gill.html", "20211223") -> 20211223 | M28: =HYPERLINK("https://docs.google.com/spreadsheets/d/1jL9gOqtcHrm8JPUtZ5KShpX7_olFuci_5Gq7xqgZKIM/edit?usp=sharing", "Sam's RNA Box #2") -> Sam's RNA Box #2 | N28: Qubit RNA HS assay | O28: y
A29: M.trossulus | B29: T04-G | C29: T04 | D29: G | E29: gill | F29: =VLOOKUP(C29,key!A:P,4,FALSE) -> control | G29: =VLOOKUP(C29,key!A:P,5,FALSE) -> 0 | H29: =VLOOKUP(C29,key!A:N,14,FALSE) -> 0 | I29: 126 | J29: 100 | K29: =I29*J29 -> 12600 | L29: =HYPERLINK("https://robertslab.github.io/sams-notebook/2021/12/23/RNA-Isolation-M.trossulus-Phenol-Gland-and-Gill.html", "20211223") -> 20211223 | M29: =HYPERLINK("https://docs.google.com/spreadsheets/d/1jL9gOqtcHrm8JPUtZ5KShpX7_olFuci_5Gq7xqgZKIM/edit?usp=sharing", "Sam's RNA Box #2") -> Sam's RNA Box #2 | N29: Qubit RNA HS assay | O29: y
A30: M.trossulus | B30: T05-G | C30: T05 | D30: G | E30: gill | F30: =VLOOKUP(C30,key!A:P,4,FALSE) -> control | G30: =VLOOKUP(C30,key!A:P,5,FALSE) -> 0 | H30: =VLOOKUP(C30,key!A:N,14,FALSE) -> 0 | I30: 160 | J30: 100 | K30: =I30*J30 -> 16000 | L30: =HYPERLINK("https://robertslab.github.io/sams-notebook/2021/12/23/RNA-Isolation-M.trossulus-Phenol-Gland-and-Gill.html", "20211223") -> 20211223 | M30: =HYPERLINK("https://docs.google.com/spreadsheets/d/1jL9gOqtcHrm8JPUtZ5KShpX7_olFuci_5Gq7xqgZKIM/edit?usp=sharing", "Sam's RNA Box #2") -> Sam's RNA Box #2 | N30: Qubit RNA HS assay | O30: y
A31: M.trossulus | B31: T06-G | C31: T06 | D31: G | E31: gill | F31: =VLOOKUP(C31,key!A:P,4,FALSE) -> control | G31: =VLOOKUP(C31,key!A:P,5,FALSE) -> 0 | H31: =VLOOKUP(C31,key!A:N,14,FALSE) -> 0 | I31: 118 | J31: 100 | K31: =I31*J31 -> 11800 | L31: =HYPERLINK("https://robertslab.github.io/sams-notebook/2021/12/23/RNA-Isolation-M.trossulus-Phenol-Gland-and-Gill.html", "20211223") -> 20211223 | M31: =HYPERLINK("https://docs.google.com/spreadsheets/d/1jL9gOqtcHrm8JPUtZ5KShpX7_olFuci_5Gq7xqgZKIM/edit?usp=sharing", "Sam's RNA Box #2") -> Sam's RNA Box #2 | N31: Qubit RNA HS assay | O31: y
A32: M.trossulus | B32: T07-G | C32: T07 | D32: G | E32: gill | F32: =VLOOKUP(C32,key!A:P,4,FALSE) -> control | G32: =VLOOKUP(C32,key!A:P,5,FALSE) -> 0 | H32: =VLOOKUP(C32,key!A:N,14,FALSE) -> 0 | I32: 106 | J32: 100 | K32: =I32*J32 -> 10600 | L32: =HYPERLINK("https://robertslab.github.io/sams-notebook/2021/12/23/RNA-Isolation-M.trossulus-Phenol-Gland-and-Gill.html", "20211223") -> 20211223 | M32: =HYPERLINK("https://docs.google.com/spreadsheets/d/1jL9gOqtcHrm8JPUtZ5KShpX7_olFuci_5Gq7xqgZKIM/edit?usp=sharing", "Sam's RNA Box #2") -> Sam's RNA Box #2 | N32: Qubit RNA HS assay | O32: y
A33: M.trossulus | B33: T08-G | C33: T08 | D33: G | E33: gill | F33: =VLOOKUP(C33,key!A:P,4,FALSE) -> control | G33: =VLOOKUP(C33,key!A:P,5,FALSE) -> 0 | H33: =VLOOKUP(C33,key!A:N,14,FALSE) -> 0 | I33: 132 | J33: 100 | K33: =I33*J33 -> 13200 | L33: =HYPERLINK("https://robertslab.github.io/sams-notebook/2021/12/23/RNA-Isolation-M.trossulus-Phenol-Gland-and-Gill.html", "20211223") -> 20211223 | M33: =HYPERLINK("https://docs.google.com/spreadsheets/d/1jL9gOqtcHrm8JPUtZ5KShpX7_olFuci_5Gq7xqgZKIM/edit?usp=sharing", "Sam's RNA Box #2") -> Sam's RNA Box #2 | N33: Qubit RNA HS assay | O33: y
A34: M.trossulus | B34: T09-G | C34: T09 | D34: G | E34: gill | F34: =VLOOKUP(C34,key!A:P,4,FALSE) -> control | G34: =VLOOKUP(C34,key!A:P,5,FALSE) -> 0 | H34: =VLOOKUP(C34,key!A:N,14,FALSE) -> 0 | I34: 130 | J34: 100 | K34: =I34*J34 -> 13000 | L34: =HYPERLINK("https://robertslab.github.io/sams-notebook/2021/12/23/RNA-Isolation-M.trossulus-Phenol-Gland-and-Gill.html", "20211223") -> 20211223 | M34: =HYPERLINK("https://docs.google.com/spreadsheets/d/1jL9gOqtcHrm8JPUtZ5KShpX7_olFuci_5Gq7xqgZKIM/edit?usp=sharing", "Sam's RNA Box #2") -> Sam's RNA Box #2 | N34: Qubit RNA HS assay | O34: y
A35: M.trossulus | B35: T10-G | C35: T10 | D35: G | E35: gill | F35: =VLOOKUP(C35,key!A:P,4,FALSE) -> control | G35: =VLOOKUP(C35,key!A:P,5,FALSE) -> 0 | H35: =VLOOKUP(C35,key!A:N,14,FALSE) -> 0 | I35: 85.6 | J35: 100 | K35: =I35*J35 -> 8560 | L35: =HYPERLINK("https://robertslab.github.io/sams-notebook/2021/12/23/RNA-Isolation-M.trossulus-Phenol-Gland-and-Gill.html", "20211223") -> 20211223 | M35: =HYPERLINK("https://docs.google.com/spreadsheets/d/1jL9gOqtcHrm8JPUtZ5KShpX7_olFuci_5Gq7xqgZKIM/edit?usp=sharing", "Sam's RNA Box #2") -> Sam's RNA Box #2 | N35: Qubit RNA HS assay | O35: y
A36: M.trossulus | B36: T11-G | C36: T11 | D36: G | E36: gill | F36: =VLOOKUP(C36,key!A:P,4,FALSE) -> control | G36: =VLOOKUP(C36,key!A:P,5,FALSE) -> 0 | H36: =VLOOKUP(C36,key!A:N,14,FALSE) -> 0 | I36: 112 | J36: 100 | K36: =I36*J36 -> 11200 | L36: =HYPERLINK("https://robertslab.github.io/sams-notebook/2021/12/23/RNA-Isolation-M.trossulus-Phenol-Gland-and-Gill.html", "20211223") -> 20211223 | M36: =HYPERLINK("https://docs.google.com/spreadsheets/d/1jL9gOqtcHrm8JPUtZ5KShpX7_olFuci_5Gq7xqgZKIM/edit?usp=sharing", "Sam's RNA Box #2") -> Sam's RNA Box #2 | N36: Qubit RNA HS assay | O36: y
A37: M.trossulus | B37: T12-G | C37: T12 | D37: G | E37: gill | F37: =VLOOKUP(C37,key!A:P,4,FALSE) -> control | G37: =VLOOKUP(C37,key!A:P,5,FALSE) -> 0 | H37: =VLOOKUP(C37,key!A:N,14,FALSE) -> 0 | I37: 132 | J37: 100 | K37: =I37*J37 -> 13200 | L37: =HYPERLINK("https://robertslab.github.io/sams-notebook/2021/12/23/RNA-Isolation-M.trossulus-Phenol-Gland-and-Gill.html", "20211223") -> 20211223 | M37: =HYPERLINK("https://docs.google.com/spreadsheets/d/1jL9gOqtcHrm8JPUtZ5KShpX7_olFuci_5Gq7xqgZKIM/edit?usp=sharing", "Sam's RNA Box #2") -> Sam's RNA Box #2 | N37: Qubit RNA HS assay | O37: y
... A49: M.trossulus | B49: T137-F_PG | C49: T137 | D49: F_PG | E49: phenol gland | F49: =VLOOKUP(C49,key!A:P,4,FALSE) -> control | G49: =VLOOKUP(C49,key!A:P,5,FALSE) -> 3 | H49: =VLOOKUP(C49,key!A:N,14,FALSE) -> 0 | I49: 92.8 | J49: 50 | K49: =I49*J49 -> 4640 | L49: =HYPERLINK("https://robertslab.github.io/sams-notebook/2021/12/23/RNA-Isolation-M.trossulus-Phenol-Gland-and-Gill.html", "20211223") -> 20211223 | M49: =HYPERLINK("https://docs.google.com/spreadsheets/d/1jL9gOqtcHrm8JPUtZ5KShpX7_olFuci_5Gq7xqgZKIM/edit?usp=sharing", "Sam's RNA Box #2") -> Sam's RNA Box #2 | N49: Qubit RNA HS assay | O49: y
A50: M.trossulus | B50: T126-G | C50: T126 | D50: G | E50: gill | F50: =VLOOKUP(C50,key!A:P,4,FALSE) -> control | G50: =VLOOKUP(C50,key!A:P,5,FALSE) -> 3 | H50: =VLOOKUP(C50,key!A:N,14,FALSE) -> 0 | I50: 79 | J50: 100 | K50: =I50*J50 -> 7900 | L50: =HYPERLINK("https://robertslab.github.io/sams-notebook/2022/01/09/RNA-Isolation-M.trossulus-Gill-and-Phenol-Gland.html", "20220109") -> 20220109 | M50: =HYPERLINK("https://docs.google.com/spreadsheets/d/1jL9gOqtcHrm8JPUtZ5KShpX7_olFuci_5Gq7xqgZKIM/edit?usp=sharing", "Sam's RNA Box #2") -> Sam's RNA Box #2 | N50: Qubit RNA HS assay | O50: y
A51: M.trossulus | B51: T127-G | C51: T127 | D51: G | E51: gill | F51: =VLOOKUP(C51,key!A:P,4,FALSE) -> control | G51: =VLOOKUP(C51,key!A:P,5,FALSE) -> 3 | H51: =VLOOKUP(C51,key!A:N,14,FALSE) -> 0 | I51: 86.6 | J51: 100 | K51: =I51*J51 -> 8660 | L51: =HYPERLINK("https://robertslab.github.io/sams-notebook/2022/01/09/RNA-Isolation-M.trossulus-Gill-and-Phenol-Gland.html", "20220109") -> 20220109 | M51: =HYPERLINK("https://docs.google.com/spreadsheets/d/1jL9gOqtcHrm8JPUtZ5KShpX7_olFuci_5Gq7xqgZKIM/edit?usp=sharing", "Sam's RNA Box #2") -> Sam's RNA Box #2 | N51: Qubit RNA HS assay | O51: y
A52: M.trossulus | B52: T128-G | C52: T128 | D52: G | E52: gill | F52: =VLOOKUP(C52,key!A:P,4,FALSE) -> control | G52: =VLOOKUP(C52,key!A:P,5,FALSE) -> 3 | H52: =VLOOKUP(C52,key!A:N,14,FALSE) -> 0 | I52: 82 | J52: 100 | K52: =I52*J52 -> 8200 | L52: =HYPERLINK("https://robertslab.github.io/sams-notebook/2022/01/09/RNA-Isolation-M.trossulus-Gill-and-Phenol-Gland.html", "20220109") -> 20220109 | M52: =HYPERLINK("https://docs.google.com/spreadsheets/d/1jL9gOqtcHrm8JPUtZ5KShpX7_olFuci_5Gq7xqgZKIM/edit?usp=sharing", "Sam's RNA Box #2") -> Sam's RNA Box #2 | N52: Qubit RNA HS assay | O52: y
A53: M.trossulus | B53: T129-G | C53: T129 | D53: G | E53: gill | F53: =VLOOKUP(C53,key!A:P,4,FALSE) -> control | G53: =VLOOKUP(C53,key!A:P,5,FALSE) -> 3 | H53: =VLOOKUP(C53,key!A:N,14,FALSE) -> 0 | I53: 45.8 | J53: 100 | K53: =I53*J53 -> 4580 | L53: =HYPERLINK("https://robertslab.github.io/sams-notebook/2022/01/09/RNA-Isolation-M.trossulus-Gill-and-Phenol-Gland.html", "20220109") -> 20220109 | M53: =HYPERLINK("https://docs.google.com/spreadsheets/d/1jL9gOqtcHrm8JPUtZ5KShpX7_olFuci_5Gq7xqgZKIM/edit?usp=sharing", "Sam's RNA Box #2") -> Sam's RNA Box #2 | N53: Qubit RNA HS assay | O53: y
A54: M.trossulus | B54: T130-G | C54: T130 | D54: G | E54: gill | F54: =VLOOKUP(C54,key!A:P,4,FALSE) -> control | G54: =VLOOKUP(C54,key!A:P,5,FALSE) -> 3 | H54: =VLOOKUP(C54,key!A:N,14,FALSE) -> 0 | I54: 62.6 | J54: 100 | K54: =I54*J54 -> 6260 | L54: =HYPERLINK("https://robertslab.github.io/sams-notebook/2022/01/09/RNA-Isolation-M.trossulus-Gill-and-Phenol-Gland.html", "20220109") -> 20220109 | M54: =HYPERLINK("https://docs.google.com/spreadsheets/d/1jL9gOqtcHrm8JPUtZ5KShpX7_olFuci_5Gq7xqgZKIM/edit?usp=sharing", "Sam's RNA Box #2") -> Sam's RNA Box #2 | N54: Qubit RNA HS assay | O54: y
A55: M.trossulus | B55: T131-G | C55: T131 | D55: G | E55: gill | F55: =VLOOKUP(C55,key!A:P,4,FALSE) -> control | G55: =VLOOKUP(C55,key!A:P,5,FALSE) -> 3 | H55: =VLOOKUP(C55,key!A:N,14,FALSE) -> 0 | I55: 31 | J55: 100 | K55: =I55*J55 -> 3100 | L55: =HYPERLINK("https://robertslab.github.io/sams-notebook/2022/01/09/RNA-Isolation-M.trossulus-Gill-and-Phenol-Gland.html", "20220109") -> 20220109 | M55: =HYPERLINK("https://docs.google.com/spreadsheets/d/1jL9gOqtcHrm8JPUtZ5KShpX7_olFuci_5Gq7xqgZKIM/edit?usp=sharing", "Sam's RNA Box #2") -> Sam's RNA Box #2 | N55: Qubit RNA HS assay | O55: y
A56: M.trossulus | B56: T132-G | C56: T132 | D56: G | E56: gill | F56: =VLOOKUP(C56,key!A:P,4,FALSE) -> control | G56: =VLOOKUP(C56,key!A:P,5,FALSE) -> 3 | H56: =VLOOKUP(C56,key!A:N,14,FALSE) -> 0 | I56: 94.8 | J56: 100 | K56: =I56*J56 -> 9480 | L56: =HYPERLINK("https://robertslab.github.io/sams-notebook/2022/01/09/RNA-Isolation-M.trossulus-Gill-and-Phenol-Gland.html", "20220109") -> 20220109 | M56: =HYPERLINK("https://docs.google.com/spreadsheets/d/1jL9gOqtcHrm8JPUtZ5KShpX7_olFuci_5Gq7xqgZKIM/edit?usp=sharing", "Sam's RNA Box #2") -> Sam's RNA Box #2 | N56: Qubit RNA HS assay | O56: y
A57: M.trossulus | B57: T133-G | C57: T133 | D57: G | E57: gill | F57: =VLOOKUP(C57,key!A:P,4,FALSE) -> control | G57: =VLOOKUP(C57,key!A:P,5,FALSE) -> 3 | H57: =VLOOKUP(C57,key!A:N,14,FALSE) -> 0 | I57: 56 | J57: 100 | K57: =I57*J57 -> 5600 | L57: =HYPERLINK("https://robertslab.github.io/sams-notebook/2022/01/09/RNA-Isolation-M.trossulus-Gill-and-Phenol-Gland.html", "20220109") -> 20220109 | M57: =HYPERLINK("https://docs.google.com/spreadsheets/d/1jL9gOqtcHrm8JPUtZ5KShpX7_olFuci_5Gq7xqgZKIM/edit?usp=sharing", "Sam's RNA Box #2") -> Sam's RNA Box #2 | N57: Qubit RNA HS assay | O57: y
A58: M.trossulus | B58: T134-G | C58: T134 | D58: G | E58: gill | F58: =VLOOKUP(C58,key!A:P,4,FALSE) -> control | G58: =VLOOKUP(C58,key!A:P,5,FALSE) -> 3 | H58: =VLOOKUP(C58,key!A:N,14,FALSE) -> 0 | I58: 32.6 | J58: 100 | K58: =I58*J58 -> 3260 | L58: =HYPERLINK("https://robertslab.github.io/sams-notebook/2022/01/09/RNA-Isolation-M.trossulus-Gill-and-Phenol-Gland.html", "20220109") -> 20220109 | M58: =HYPERLINK("https://docs.google.com/spreadsheets/d/1jL9gOqtcHrm8JPUtZ5KShpX7_olFuci_5Gq7xqgZKIM/edit?usp=sharing", "Sam's RNA Box #2") -> Sam's RNA Box #2 | N58: Qubit RNA HS assay | O58: y
A59: M.trossulus | B59: T135-G | C59: T135 | D59: G | E59: gill | F59: =VLOOKUP(C59,key!A:P,4,FALSE) -> control | G59: =VLOOKUP(C59,key!A:P,5,FALSE) -> 3 | H59: =VLOOKUP(C59,key!A:N,14,FALSE) -> 0 | I59: 44.2 | J59: 100 | K59: =I59*J59 -> 4420 | L59: =HYPERLINK("https://robertslab.github.io/sams-notebook/2022/01/09/RNA-Isolation-M.trossulus-Gill-and-Phenol-Gland.html", "20220109") -> 20220109 | M59: =HYPERLINK("https://docs.google.com/spreadsheets/d/1jL9gOqtcHrm8JPUtZ5KShpX7_olFuci_5Gq7xqgZKIM/edit?usp=sharing", "Sam's RNA Box #2") -> Sam's RNA Box #2 | N59: Qubit RNA HS assay | O59: y
A60: M.trossulus | B60: T136-G | C60: T136 | D60: G | E60: gill | F60: =VLOOKUP(C60,key!A:P,4,FALSE) -> control | G60: =VLOOKUP(C60,key!A:P,5,FALSE) -> 3 | H60: =VLOOKUP(C60,key!A:N,14,FALSE) -> 0 | I60: 48.6 | J60: 100 | K60: =I60*J60 -> 4860 | L60: =HYPERLINK("https://robertslab.github.io/sams-notebook/2022/01/09/RNA-Isolation-M.trossulus-Gill-and-Phenol-Gland.html", "20220109") -> 20220109 | M60: =HYPERLINK("https://docs.google.com/spreadsheets/d/1jL9gOqtcHrm8JPUtZ5KShpX7_olFuci_5Gq7xqgZKIM/edit?usp=sharing", "Sam's RNA Box #2") -> Sam's RNA Box #2 | N60: Qubit RNA HS assay | O60: y
A61: M.trossulus | B61: T137-G | C61: T137 | D61: G | E61: gill | F61: =VLOOKUP(C61,key!A:P,4,FALSE) -> control | G61: =VLOOKUP(C61,key!A:P,5,FALSE) -> 3 | H61: =VLOOKUP(C61,key!A:N,14,FALSE) -> 0 | I61: 20.2 | J61: 100 | K61: =I61*J61 -> 2020 | L61: =HYPERLINK("https://robertslab.github.io/sams-notebook/2022/01/09/RNA-Isolation-M.trossulus-Gill-and-Phenol-Gland.html", "20220109") -> 20220109 | M61: =HYPERLINK("https://docs.google.com/spreadsheets/d/1jL9gOqtcHrm8JPUtZ5KShpX7_olFuci_5Gq7xqgZKIM/edit?usp=sharing", "Sam's RNA Box #2") -> Sam's RNA Box #2 | N61: Qubit RNA HS assay | O61: y
... A68: M.trossulus | B68: T51-F_PG | C68: T51 | D68: F_PG | E68: phenol gland | F68: =VLOOKUP(C68,key!A:P,4,FALSE) -> DO | G68: =VLOOKUP(C68,key!A:P,5,FALSE) -> 3 | H68: =VLOOKUP(C68,key!A:N,14,FALSE) -> 1 | I68: 124 | J68: 100 | K68: =I68*J68 -> 12400 | L68: =HYPERLINK("https://robertslab.github.io/sams-notebook/2022/01/09/RNA-Isolation-M.trossulus-Gill-and-Phenol-Gland.html", "20220109") -> 20220109 | M68: =HYPERLINK("https://docs.google.com/spreadsheets/d/1jL9gOqtcHrm8JPUtZ5KShpX7_olFuci_5Gq7xqgZKIM/edit?usp=sharing", "Sam's RNA Box #2") -> Sam's RNA Box #2 | N68: Qubit RNA HS assay | O68: y
...

Sheet condition
A1: ID | B1: species | C1: following | D1: trt | E1: day | F1: combo | G1: sdate | H1: L | I1: H | J1: W | K1: V | L1: total_mass | M1: gonad_mass | N1: CI | O1: GI
A2: G50 | B2: gallo | C2: no | D2: baseline | E2: 0 | F2: gallo-baseline | G2: 44491 | H2: 64 | I2: 36 | J2: 23 | K2: 71 | L2: 1.22 | M2: 0.33 | N2: 4.6539307 | O2: 27
A3: G51 | B3: gallo | C3: no | D3: baseline | E3: 0 | F3: gallo-baseline | G3: 44491 | H3: 59 | I3: 32 | J3: 22 | K3: 55 | L3: 1.11 | M3: 0.32 | N3: 5.4046421 | O3: 29
A4: G52 | B4: gallo | C4: no | D4: baseline | E4: 0 | F4: gallo-baseline | G4: 44491 | H4: 57 | I4: 30 | J4: 20 | K4: 46 | L4: 1.27 | M4: 0.45 | N4: 6.8577106 | O4: 35
A5: G53 | B5: gallo | C5: no | D5: baseline | E5: 0 | F5: gallo-baseline | G5: 44491 | H5: 58 | I5: 32 | J5: 22 | K5: 54 | L5: 0.87 | M5: 0.17 | N5: 4.4589774 | O5: 20
A6: G54 | B6: gallo | C6: no | D6: baseline | E6: 0 | F6: gallo-baseline | G6: 44491 | H6: 65 | I6: 32 | J6: 25 | K6: 69 | L6: 1.7 | M6: 0.66 | N6: 6.1902594 | O6: 39
A7: G55 | B7: gallo | C7: no | D7: baseline | E7: 0 | F7: gallo-baseline | G7: 44491 | H7: 58 | I7: 32 | J7: 22 | K7: 54 | L7: 1.06 | M7: 0.29 | N7: 5.4327771 | O7: 27
A8: G56 | B8: gallo | C8: no | D8: baseline | E8: 0 | F8: gallo-baseline | G8: 44491 | H8: 57 | I8: 31 | J8: 19 | K8: 45 | L8: 1.05 | M8: 0.19 | N8: 5.6697607 | O8: 18
A9: G57 | B9: gallo | C9: no | D9: baseline | E9: 0 | F9: gallo-baseline | G9: 44491 | H9: 56 | I9: 32 | J9: 20 | K9: 48 | L9: 0.68 | M9: 0.14 | N9: 3.8720845 | O9: 21
A10: G58 | B10: gallo | C10: no | D10: baseline | E10: 0 | F10: gallo-baseline | G10: 44491 | H10: 63 | I10: 34 | J10: 22 | K10: 63 | L10: 1.11 | M10: 0.29 | N10: 4.4391654 | O10: 26
A11: G59 | B11: gallo | C11: no | D11: baseline | E11: 0 | F11: gallo-baseline | G11: 44491 | H11: 67 | I11: 35 | J11: 22 | K11: 69 | L11: 1.33 | M11: 0.43 | N11: 4.4220865 | O11: 32
A12: G60 | B12: gallo | C12: no | D12: baseline | E12: 0 | F12: gallo-baseline | G12: 44491 | H12: 55 | I12: 30 | J12: 21 | K12: 46 | L12: 0.73 | M12: 0.25 | N12: 4.3876784 | O12: 34
A13: G61 | B13: gallo | C13: no | D13: baseline | E13: 0 | F13: gallo-baseline | G13: 44491 | H13: 42 | I13: 22 | J13: 15 | K13: 18 | L13: 0.43 | M13: 0.13 | N13: 5.8039089 | O13: 30
... A121: T194 | B121: tross | C121: no | D121: DO | E121: 3 | F121: tross-DO | G121: 44498 | H121: 43 | I121: 20 | J121: 16 | K121: 18 | L121: 0.39 | M121: 0.08 | N121: 4.9052285 | O121: 21

Sheet paired-thread_count
A1: ID | B1: time | C1: species | D1: trt | E1: combo | F1: thread
A2: G13 | B2: before | C2: gallo | D2: OA | E2: =B2&"-"&C2&"-"&D2 -> before-gallo-OA | F2: 7
A3: G13 | B3: after | C3: gallo | D3: OA | E3: =B3&"-"&C3&"-"&D3 -> after-gallo-OA | F3: 15
A4: G14 | B4: before | C4: gallo | D4: OA | E4: =B4&"-"&C4&"-"&D4 -> before-gallo-OA | F4: 8
A5: G14 | B5: after | C5: gallo | D5: OA | E5: =B5&"-"&C5&"-"&D5 -> after-gallo-OA | F5: 25
A6: G15 | B6: before | C6: gallo | D6: OA | E6: =B6&"-"&C6&"-"&D6 -> before-gallo-OA | F6: 15
A7: G15 | B7: after | C7: gallo | D7: OA | E7: =B7&"-"&C7&"-"&D7 -> after-gallo-OA | F7: 14
A8: G16 | B8: before | C8: gallo | D8: OA | E8: =B8&"-"&C8&"-"&D8 -> before-gallo-OA | F8: 12
A9: G16 | B9: after | C9: gallo | D9: OA | E9: =B9&"-"&C9&"-"&D9 -> after-gallo-OA | F9: 10
A10: G17 | B10: before | C10: gallo | D10: OA | E10: =B10&"-"&C10&"-"&D10 -> before-gallo-OA | F10: 14
A11: G17 | B11: after | C11: gallo | D11: OA | E11: =B11&"-"&C11&"-"&D11 -> after-gallo-OA | F11: 26
A12: G18 | B12: before | C12: gallo | D12: OA | E12: =B12&"-"&C12&"-"&D12 -> before-gallo-OA | F12: 8
A13: G18 | B13: after | C13: gallo | D13: OA | E13: =B13&"-"&C13&"-"&D13 -> after-gallo-OA | F13: 15
... A101: T58 | B101: after | C101: tross | D101: DO | E101: =B101&"-"&C101&"-"&D101 -> after-tross-DO | F101: 6
