Workbook

Sheet key
A1: ID | B1: species | C1: following | D1: trt | E1: day | F1: sdate | G1: L | H1: H | I1: W | J1: V | K1: thread_before | L1: thread_after | M1: thread_both | N1: thread_count_before | O1: thread_count_after
A2: G01 | B2: gallo | C2: no | D2: control | E2: 0 | F2: 44491 | G2: 62 | H2: 33 | I2: 24 | J2: =ROUND((4/3)*(G2/10)*(H2/10)*(I2/10),0) -> 65 | K2: 1 | L2: 0 | M2: =IF(K2+L2=2,1,0) -> 0 | N2: 8
A3: G02 | B3: gallo | C3: no | D3: control | E3: 0 | F3: 44491 | G3: 64 | H3: 35 | I3: 24 | J3: =ROUND((4/3)*(G3/10)*(H3/10)*(I3/10),0) -> 72 | K3: 1 | L3: 0 | M3: =IF(K3+L3=2,1,0) -> 0 | N3: 12
A4: G03 | B4: gallo | C4: no | D4: control | E4: 0 | F4: 44491 | G4: 59 | H4: 34 | I4: 23 | J4: =ROUND((4/3)*(G4/10)*(H4/10)*(I4/10),0) -> 62 | K4: 1 | L4: 0 | M4: =IF(K4+L4=2,1,0) -> 0 | N4: 6
A5: G04 | B5: gallo | C5: no | D5: control | E5: 0 | F5: 44491 | G5: 51 | H5: 30 | I5: 19 | J5: =ROUND((4/3)*(G5/10)*(H5/10)*(I5/10),0) -> 39 | K5: 1 | L5: 0 | M5: =IF(K5+L5=2,1,0) -> 0 | N5: 6
A6: G05 | B6: gallo | C6: no | D6: control | E6: 0 | F6: 44491 | G6: 63 | H6: 37 | I6: 23 | J6: =ROUND((4/3)*(G6/10)*(H6/10)*(I6/10),0) -> 71 | K6: 1 | L6: 0 | M6: =IF(K6+L6=2,1,0) -> 0 | N6: 7
A7: G06 | B7: gallo | C7: no | D7: control | E7: 0 | F7: 44491 | G7: 62 | H7: 33 | I7: 24 | J7: =ROUND((4/3)*(G7/10)*(H7/10)*(I7/10),0) -> 65 | K7: 1 | L7: 0 | M7: =IF(K7+L7=2,1,0) -> 0 | N7: 9
A8: G07 | B8: gallo | C8: no | D8: control | E8: 0 | F8: 44491 | G8: 71 | H8: 40 | I8: 25 | J8: =ROUND((4/3)*(G8/10)*(H8/10)*(I8/10),0) -> 95 | K8: 1 | L8: 0 | M8: =IF(K8+L8=2,1,0) -> 0 | N8: 12
A9: G08 | B9: gallo | C9: no | D9: control | E9: 0 | F9: 44491 | G9: 67 | H9: 34 | I9: 24 | J9: =ROUND((4/3)*(G9/10)*(H9/10)*(I9/10),0) -> 73 | K9: 1 | L9: 0 | M9: =IF(K9+L9=2,1,0) -> 0 | N9: 14
A10: G09 | B10: gallo | C10: no | D10: control | E10: 0 | F10: 44491 | G10: 58 | H10: 32 | I10: 23 | J10: =ROUND((4/3)*(G10/10)*(H10/10)*(I10/10),0) -> 57 | K10: 1 | L10: 0 | M10: =IF(K10+L10=2,1,0) -> 0 | N10: 11
A11: G10 | B11: gallo | C11: no | D11: control | E11: 0 | F11: 44491 | G11: 67 | H11: 34 | I11: 24 | J11: =ROUND((4/3)*(G11/10)*(H11/10)*(I11/10),0) -> 73 | K11: 1 | L11: 0 | M11: =IF(K11+L11=2,1,0) -> 0 | N11: 7
A12: G11 | B12: gallo | C12: no | D12: control | E12: 0 | F12: 44491 | G12: 63 | H12: 34 | I12: 20 | J12: =ROUND((4/3)*(G12/10)*(H12/10)*(I12/10),0) -> 57 | K12: 1 | L12: 0 | M12: =IF(K12+L12=2,1,0) -> 0 | N12: 9
A13: G12 | B13: gallo | C13: no | D13: control | E13: 0 | F13: 44491 | G13: 65 | H13: 36 | I13: 23 | J13: =ROUND((4/3)*(G13/10)*(H13/10)*(I13/10),0) -> 72 | K13: 1 | L13: 0 | M13: =IF(K13+L13=2,1,0) -> 0 | N13: 13
A14: G13 | B14: gallo | C14: yes | D14: OA | E14: 3 | F14: 44498 | G14: 59 | H14: 32 | I14: 20 | J14: =ROUND((4/3)*(G14/10)*(H14/10)*(I14/10),0) -> 50 | K14: 1 | L14: 1 | M14: =IF(K14+L14=2,1,0) -> 1 | N14: 7 | O14: 15
A15: G14 | B15: gallo | C15: yes | D15: OA | E15: 3 | F15: 44498 | G15: 59 | H15: 37 | I15: 22 | J15: =ROUND((4/3)*(G15/10)*(H15/10)*(I15/10),0) -> 64 | K15: 1 | L15: 1 | M15: =IF(K15+L15=2,1,0) -> 1 | N15: 8 | O15: 25
A16: G15 | B16: gallo | C16: yes | D16: OA | E16: 3 | F16: 44498 | G16: 70 | H16: 39 | I16: 26 | J16: =ROUND((4/3)*(G16/10)*(H16/10)*(I16/10),0) -> 95 | K16: 1 | L16: 1 | M16: =IF(K16+L16=2,1,0) -> 1 | N16: 15 | O16: 14
A17: G16 | B17: gallo | C17: yes | D17: OA | E17: 3 | F17: 44498 | G17: 66 | H17: 36 | I17: 24 | J17: =ROUND((4/3)*(G17/10)*(H17/10)*(I17/10),0) -> 76 | K17: 1 | L17: 1 | M17: =IF(K17+L17=2,1,0) -> 1 | N17: 12 | O17: 10
A18: G17 | B18: gallo | C18: yes | D18: OA | E18: 3 | F18: 44498 | G18: 70 | H18: 40 | I18: 25 | J18: =ROUND((4/3)*(G18/10)*(H18/10)*(I18/10),0) -> 93 | K18: 1 | L18: 1 | M18: =IF(K18+L18=2,1,0) -> 1 | N18: 14 | O18: 26
A19: G18 | B19: gallo | C19: yes | D19: OA | E19: 3 | F19: 44498 | G19: 76 | H19: 40 | I19: 27 | J19: =ROUND((4/3)*(G19/10)*(H19/10)*(I19/10),0) -> 109 | K19: 1 | L19: 1 | M19: =IF(K19+L19=2,1,0) -> 1 | N19: 8 | O19: 15
A20: G19 | B20: gallo | C20: yes | D20: OA | E20: 1 | G20: 71 | H20: 38 | I20: 29 | J20: =ROUND((4/3)*(G20/10)*(H20/10)*(I20/10),0) -> 104 | K20: 1 | L20: 0 | M20: =IF(K20+L20=2,1,0) -> 0 | N20: 24
A21: G20 | B21: gallo | C21: yes | D21: OW | E21: 1 | G21: 61 | H21: 31 | I21: 21 | J21: =ROUND((4/3)*(G21/10)*(H21/10)*(I21/10),0) -> 53 | K21: 1 | L21: 0 | M21: =IF(K21+L21=2,1,0) -> 0 | N21: 10
A22: G21 | B22: gallo | C22: yes | D22: OW | E22: 3 | F22: 44498 | G22: 64 | H22: 35 | I22: 23 | J22: =ROUND((4/3)*(G22/10)*(H22/10)*(I22/10),0) -> 69 | K22: 1 | L22: 1 | M22: =IF(K22+L22=2,1,0) -> 1 | N22: 20 | O22: 7
A23: G22 | B23: gallo | C23: yes | D23: OW | E23: 1 | G23: 55 | H23: 32 | I23: 21 | J23: =ROUND((4/3)*(G23/10)*(H23/10)*(I23/10),0) -> 49 | K23: 1 | L23: 0 | M23: =IF(K23+L23=2,1,0) -> 0 | N23: 8
A24: G23 | B24: gallo | C24: yes | D24: OW | E24: 1 | G24: 55 | H24: 31 | I24: 20 | J24: =ROUND((4/3)*(G24/10)*(H24/10)*(I24/10),0) -> 45 | K24: 1 | L24: 0 | M24: =IF(K24+L24=2,1,0) -> 0 | N24: 7
A25: G24 | B25: gallo | C25: yes | D25: OW | E25: 3 | F25: 44498 | G25: 56 | H25: 30 | I25: 24 | J25: =ROUND((4/3)*(G25/10)*(H25/10)*(I25/10),0) -> 54 | K25: 1 | L25: 1 | M25: =IF(K25+L25=2,1,0) -> 1 | N25: 16 | O25: 11
A26: G25 | B26: gallo | C26: yes | D26: OW | E26: 3 | F26: 44498 | G26: 78 | H26: 41 | I26: 29 | J26: =ROUND((4/3)*(G26/10)*(H26/10)*(I26/10),0) -> 124 | K26: 1 | L26: 1 | M26: =IF(K26+L26=2,1,0) -> 1 | N26: 8 | O26: 8
A27: G26 | B27: gallo | C27: yes | D27: OW | E27: 3 | F27: 44498 | G27: 59 | H27: 33 | I27: 21 | J27: =ROUND((4/3)*(G27/10)*(H27/10)*(I27/10),0) -> 55 | K27: 1 | L27: 1 | M27: =IF(K27+L27=2,1,0) -> 1 | N27: 11 | O27: 9
A28: G27 | B28: gallo | C28: yes | D28: DO | E28: 1 | G28: 68 | H28: 38 | I28: 25 | J28: =ROUND((4/3)*(G28/10)*(H28/10)*(I28/10),0) -> 86 | K28: 1 | L28: 0 | M28: =IF(K28+L28=2,1,0) -> 0 | N28: 7
A29: G28 | B29: gallo | C29: yes | D29: DO | E29: 3 | F29: 44498 | G29: 58 | H29: 32 | I29: 20 | J29: =ROUND((4/3)*(G29/10)*(H29/10)*(I29/10),0) -> 49 | K29: 1 | L29: 0 | M29: =IF(K29+L29=2,1,0) -> 0 | N29: 16
A30: G29 | B30: gallo | C30: yes | D30: DO | E30: 1 | G30: 55 | H30: 30 | I30: 21 | J30: =ROUND((4/3)*(G30/10)*(H30/10)*(I30/10),0) -> 46 | K30: 1 | L30: 0 | M30: =IF(K30+L30=2,1,0) -> 0 | N30: 15
A31: G30 | B31: gallo | C31: yes | D31: DO | E31: 1 | G31: 65 | H31: 34 | I31: 23 | J31: =ROUND((4/3)*(G31/10)*(H31/10)*(I31/10),0) -> 68 | K31: 1 | L31: 0 | M31: =IF(K31+L31=2,1,0) -> 0 | N31: 9
A32: G31 | B32: gallo | C32: yes | D32: DO | E32: 3 | F32: 44498 | G32: 59 | H32: 32 | I32: 24 | J32: =ROUND((4/3)*(G32/10)*(H32/10)*(I32/10),0) -> 60 | K32: 1 | L32: 0 | M32: =IF(K32+L32=2,1,0) -> 0 | N32: 14
A33: G32 | B33: gallo | C33: yes | D33: DO | E33: 3 | F33: 44498 | G33: 67 | H33: 35 | I33: 25 | J33: =ROUND((4/3)*(G33/10)*(H33/10)*(I33/10),0) -> 78 | K33: 1 | L33: 0 | M33: =IF(K33+L33=2,1,0) -> 0 | N33: 8
A34: G33 | B34: gallo | C34: yes | D34: DO | E34: 3 | F34: 44498 | G34: 46 | H34: 26 | I34: 15 | J34: =ROUND((4/3)*(G34/10)*(H34/10)*(I34/10),0) -> 24 | K34: 1 | L34: 0 | M34: =IF(K34+L34=2,1,0) -> 0 | N34: 5
A35: G34 | B35: gallo | C35: yes | D35: DO | E35: 3 | F35: 44498 | G35: 55 | H35: 32 | I35: 20 | J35: =ROUND((4/3)*(G35/10)*(H35/10)*(I35/10),0) -> 47 | K35: 1 | L35: 0 | M35: =IF(K35+L35=2,1,0) -> 0 | N35: 6
A36: G35 | B36: gallo | C36: no | D36: OA | E36: 1 | F36: 44496 | G36: 72 | H36: 42 | I36: 25 | J36: =ROUND((4/3)*(G36/10)*(H36/10)*(I36/10),0) -> 101 | K36: 0 | L36: 0 | M36: =IF(K36+L36=2,1,0) -> 0
A37: G36 | B37: gallo | C37: no | D37: OA | E37: 1 | F37: 44496 | G37: 64 | H37: 30 | I37: 22 | J37: =ROUND((4/3)*(G37/10)*(H37/10)*(I37/10),0) -> 56 | K37: 0 | L37: 0 | M37: =IF(K37+L37=2,1,0) -> 0
A38: G37 | B38: gallo | C38: no | D38: OA | E38: 1 | F38: 44496 | G38: 57 | H38: 31 | I38: 20 | J38: =ROUND((4/3)*(G38/10)*(H38/10)*(I38/10),0) -> 47 | K38: 0 | L38: 0 | M38: =IF(K38+L38=2,1,0) -> 0
A39: G38 | B39: gallo | C39: no | D39: OA | E39: 1 | F39: 44496 | G39: 61 | H39: 39 | I39: 22 | J39: =ROUND((4/3)*(G39/10)*(H39/10)*(I39/10),0) -> 70 | K39: 0 | L39: 0 | M39: =IF(K39+L39=2,1,0) -> 0
A40: G39 | B40: gallo | C40: no | D40: OA | E40: 1 | F40: 44496 | G40: 59 | H40: 30 | I40: 21 | J40: =ROUND((4/3)*(G40/10)*(H40/10)*(I40/10),0) -> 50 | K40: 0 | L40: 0 | M40: =IF(K40+L40=2,1,0) -> 0
...

Sheet tissue-for-RNA
A1: ID | B1: trt | C1: day | D1: species | E1: day
A2: G13 | B2: =VLOOKUP(A2,key!A:E,4,FALSE) -> OA | C2: =VLOOKUP(A2,key!A:E,5,FALSE) -> 3 | D2: gallo | E2: 3
A3: G14 | B3: =VLOOKUP(A3,key!A:E,4,FALSE) -> OA | C3: =VLOOKUP(A3,key!A:E,5,FALSE) -> 3 | D3: gallo | E3: 3
A4: G15 | B4: =VLOOKUP(A4,key!A:E,4,FALSE) -> OA | C4: =VLOOKUP(A4,key!A:E,5,FALSE) -> 3 | D4: gallo | E4: 3
A5: G21 | B5: =VLOOKUP(A5,key!A:E,4,FALSE) -> OW | C5: =VLOOKUP(A5,key!A:E,5,FALSE) -> 3 | D5: gallo | E5: 3
A6: G24 | B6: =VLOOKUP(A6,key!A:E,4,FALSE) -> OW | C6: =VLOOKUP(A6,key!A:E,5,FALSE) -> 3 | D6: gallo | E6: 3
A7: G25 | B7: =VLOOKUP(A7,key!A:E,4,FALSE) -> OW | C7: =VLOOKUP(A7,key!A:E,5,FALSE) -> 3 | D7: gallo | E7: 3
A8: G26 | B8: =VLOOKUP(A8,key!A:E,4,FALSE) -> OW | C8: =VLOOKUP(A8,key!A:E,5,FALSE) -> 3 | D8: gallo | E8: 3
A9: G16 | B9: =VLOOKUP(A9,key!A:E,4,FALSE) -> OA | C9: =VLOOKUP(A9,key!A:E,5,FALSE) -> 3 | D9: gallo | E9: 3
A10: G17 | B10: =VLOOKUP(A10,key!A:E,4,FALSE) -> OA | C10: =VLOOKUP(A10,key!A:E,5,FALSE) -> 3 | D10: gallo | E10: 3
A11: G18 | B11: =VLOOKUP(A11,key!A:E,4,FALSE) -> OA | C11: =VLOOKUP(A11,key!A:E,5,FALSE) -> 3 | D11: gallo | E11: 3
A12: G01 | B12: =VLOOKUP(A12,key!A:E,4,FALSE) -> control | C12: =VLOOKUP(A12,key!A:E,5,FALSE) -> 0 | D12: gallo | E12: 0
A13: G02 | B13: =VLOOKUP(A13,key!A:E,4,FALSE) -> control | C13: =VLOOKUP(A13,key!A:E,5,FALSE) -> 0 | D13: gallo | E13: 0
... A54: G70 | B54: =VLOOKUP(A54,key!A:E,4,FALSE) -> DO | C54: =VLOOKUP(A54,key!A:E,5,FALSE) -> 3 | D54: gallo | E54: 3

Sheet condition
A1: ID | B1: species | C1: following | D1: trt | E1: day | F1: combo | G1: sdate | H1: L | I1: H | J1: W | K1: V | L1: total_mass | M1: gonad_mass | N1: CI | O1: GI
A2: G50 | B2: gallo | C2: no | D2: baseline | E2: 0 | F2: gallo-baseline | G2: 44491 | H2: 64 | I2: 36 | J2: 23 | K2: 71 | L2: 1.22 | M2: 0.33 | N2: 4.6539307 | O2: 27
A3: G51 | B3: gallo | C3: no | D3: baseline | E3: 0 | F3: gallo-baseline | G3: 44491 | H3: 59 | I3: 32 | J3: 22 | K3: 55 | L3: 1.11 | M3: 0.32 | N3: 5.4046421 | O3: 29
A4: G52 | B4: gallo | C4: no | D4: baseline | E4: 0 | F4: gallo-baseline | G4: 44491 | H4: 57 | I4: 30 | J4: 20 | K4: 46 | L4: 1.27 | M4: 0.45 | N4: 6.8577106 | O4: 35
A5: G53 | B5: gallo | C5: no | D5: baseline | E5: 0 | F5: gallo-baseline | G5: 44491 | H5: 58 | I5: 32 | J5: 22 | K5: 54 | L5: 0.87 | M5: 0.17 | N5: 4.4589774 | O5: 20
A6: G54 | B6: gallo | C6: no | D6: baseline | E6: 0 | F6: gallo-baseline | G6: 44491 | H6: 65 | I6: 32 | J6: 25 | K6: 69 | L6: 1.7 | M6: 0.66 | N6: 6.1902594 | O6: 39
A7: G55 | B7: gallo | C7: no | D7: baseline | E7: 0 | F7: gallo-baseline | G7: 44491 | H7: 58 | I7: 32 | J7: 22 | K7: 54 | L7: 1.06 | M7: 0.29 | N7: 5.4327771 | O7: 27
A8: G56 | B8: gallo | C8: no | D8: baseline | E8: 0 | F8: gallo-baseline | G8: 44491 | H8: 57 | I8: 31 | J8: 19 | K8: 45 | L8: 1.05 | M8: 0.19 | N8: 5.6697607 | O8: 18
A9: G57 | B9: gallo | C9: no | D9: baseline | E9: 0 | F9: gallo-baseline | G9: 44491 | H9: 56 | I9: 32 | J9: 20 | K9: 48 | L9: 0.68 | M9: 0.14 | N9: 3.8720845 | O9: 21
A10: G58 | B10: gallo | C10: no | D10: baseline | E10: 0 | F10: gallo-baseline | G10: 44491 | H10: 63 | I10: 34 | J10: 22 | K10: 63 | L10: 1.11 | M10: 0.29 | N10: 4.4391654 | O10: 26
A11: G59 | B11: gallo | C11: no | D11: baseline | E11: 0 | F11: gallo-baseline | G11: 44491 | H11: 67 | I11: 35 | J11: 22 | K11: 69 | L11: 1.33 | M11: 0.43 | N11: 4.4220865 | O11: 32
A12: G60 | B12: gallo | C12: no | D12: baseline | E12: 0 | F12: gallo-baseline | G12: 44491 | H12: 55 | I12: 30 | J12: 21 | K12: 46 | L12: 0.73 | M12: 0.25 | N12: 4.3876784 | O12: 34
A13: G61 | B13: gallo | C13: no | D13: baseline | E13: 0 | F13: gallo-baseline | G13: 44491 | H13: 42 | I13: 22 | J13: 15 | K13: 18 | L13: 0.43 | M13: 0.13 | N13: 5.8039089 | O13: 30
... A61: G105 | B61: gallo | C61: no | D61: final | E61: 3 | F61: gallo-final | G61: 44498 | H61: 54 | I61: 30 | J61: 17 | K61: 37 | L61: 0.52 | M61: 0.14 | N61: 3.3023421 | O61: 27

Sheet paired-thread_count
A1: ID | B1: time | C1: species | D1: trt | E1: combo | F1: thread
A2: G13 | B2: before | C2: gallo | D2: OA | E2: =B2&"-"&C2&"-"&D2 -> before-gallo-OA | F2: 7
A3: G13 | B3: after | C3: gallo | D3: OA | E3: =B3&"-"&C3&"-"&D3 -> after-gallo-OA | F3: 15
A4: G14 | B4: before | C4: gallo | D4: OA | E4: =B4&"-"&C4&"-"&D4 -> before-gallo-OA | F4: 8
A5: G14 | B5: after | C5: gallo | D5: OA | E5: =B5&"-"&C5&"-"&D5 -> after-gallo-OA | F5: 25
A6: G15 | B6: before | C6: gallo | D6: OA | E6: =B6&"-"&C6&"-"&D6 -> before-gallo-OA | F6: 15
A7: G15 | B7: after | C7: gallo | D7: OA | E7: =B7&"-"&C7&"-"&D7 -> after-gallo-OA | F7: 14
A8: G16 | B8: before | C8: gallo | D8: OA | E8: =B8&"-"&C8&"-"&D8 -> before-gallo-OA | F8: 12
A9: G16 | B9: after | C9: gallo | D9: OA | E9: =B9&"-"&C9&"-"&D9 -> after-gallo-OA | F9: 10
A10: G17 | B10: before | C10: gallo | D10: OA | E10: =B10&"-"&C10&"-"&D10 -> before-gallo-OA | F10: 14
A11: G17 | B11: after | C11: gallo | D11: OA | E11: =B11&"-"&C11&"-"&D11 -> after-gallo-OA | F11: 26
A12: G18 | B12: before | C12: gallo | D12: OA | E12: =B12&"-"&C12&"-"&D12 -> before-gallo-OA | F12: 8
A13: G18 | B13: after | C13: gallo | D13: OA | E13: =B13&"-"&C13&"-"&D13 -> after-gallo-OA | F13: 15
... A37: G27 | B37: after | C37: gallo | D37: OW | E37: =B37&"-"&C37&"-"&D37 -> after-gallo-OW | F37: 8
